Workbook

Sheet TRANG CHỦ
B2: ĐẤU TRƯỜNG CHÂN LÝ
B3: HƯỚNG DẪN TOÀN DIỆN LÊN THÁCH ĐẤU
B5: Mùa 18 · Đại Ngàn Kỳ Bí · Đội hình mạnh – Lên đồ – Lõi – Tinh Linh – Kinh tế – Xếp vị trí
F7: TÀI LIỆU v1.8 · CẬP NHẬT 06/10/2026 · BẢN 18.3b + XEM TRƯỚC 18.4
B11: CÁCH DÙNG – CHỈ CẦN BẤM CHỌN
B12: BƯỚC 1 | F12: BƯỚC 2 | J12: BƯỚC 3
B13: Tìm ô VÀNG viền vàng | F13: Chọn đội hình / tình huống | J13: Làm theo & tự chấm
B14: Mọi ô màu vàng đều có nút ▼ – bấm vào để chọn, không cần gõ. | F14: Trang CHỌN ĐỘI HÌNH & TRỢ LÝ VÁN ĐẤU tự hiện lộ trình, đồ, vị trí. | J14: Theo khuyến nghị từng vòng; chấm thói quen ở LỘ TRÌNH THÁCH ĐẤU.
B17: MỤC LỤC (bấm để mở)
B18: 🏳 CHỌN ẤN → ĐỘI HÌNH | E18: MỚI: chọn 3 Ấn → ra đội hình mạnh nhất + người đeo + đồ | I18: 🧠 LÕI → CÁCH ĐÁNH | L18: MỚI: lõi cho Vàng / Đồ / Ấn… → cách đánh tối ưu
B19: 🖼 HÌNH ẢNH ĐỘI HÌNH | E19: Hình ảnh các đội hình: tướng, trang bị, lõi | I19: 🎯 CHỌN ĐỘI HÌNH | L19: Chọn đội hình mạnh: lộ trình, đội hình cuối, lên đồ chuẩn, vị trí
B20: 🧭 TRỢ LÝ VÁN ĐẤU | E20: Trợ lý: đang ở vòng nào, nên lên cấp hay đổi tướng? | I20: ⚔️ LÊN ĐỒ | L20: Ghép 2 mảnh đồ, đồ khởi đầu → hướng đội hình, Tạo Tác
B21: 🏆 XẾP HẠNG ĐỘI HÌNH | E21: Xếp hạng đội hình S/A/B/C (có lọc) | I21: 🇻🇳 MÁY CHỦ VN - TRUNG - HÀN | L21: Số liệu máy chủ VIỆT NAM + Trung/Hàn & cách build
B22: 🏆 LÕI ĂN TOP 1 | E22: LÕI ĂN TOP 1: lõi phải ép + cách chơi ngay | I22: ✨ LÕI NÂNG CẤP | L22: Quy tắc chọn Lõi 2-1 / 3-2 / 4-2 + lõi mạnh
B23: 🌿 TỘC HỆ & TƯỚNG | E23: Tra cứu tộc/hệ, mốc kích hoạt, 65 tướng | I23: 🔮 TINH LINH & VÒNG ĐẤU | L23: Tinh Linh (cơ chế mùa) + bản đồ vòng đấu
B24: 💰 KINH TẾ & CẤP | E24: Tỉ lệ cửa hàng, máy tính đổi tướng, kinh tế, lộ trình cấp | I24: 🗺️ XẾP VỊ TRÍ | L24: Sơ đồ bàn cờ mẫu + 10 nguyên tắc triển khai
B25: 🚀 LỘ TRÌNH THÁCH ĐẤU | E25: 20 thói quen Thách Đấu, lỗi thường gặp, kế hoạch rank | I25: 📖 TỪ ĐIỂN THUẬT NGỮ | L25: Giải thích các từ lóng hay gặp khi xem hướng dẫn
B26: 📚 NGUỒN & PHIÊN BẢN | E26: Nguồn dữ liệu & nhật ký phiên bản
B28: TOP ĐỘI HÌNH 18.3b (tổng hợp quốc tế) – số liệu riêng VN xem trang MÁY CHỦ VN · chọn theo Ấn xem trang CHỌN ẤN
B29: # | C29: Hạng | D29: Đội hình | H29: Lối chơi | J29: Chủ lực chính | L29: Lõi nên tìm
B30: 1 | C30: S | D30: Đao Phủ Azir – Soraka & Zyra (Thực Vật) | H30: Lên 8 nhanh | J30: Soraka | L30: Thực Vật Hấp Thụ
B31: 2 | C31: S | D31: Nidalee & Aphelios Mặt Trăng | H31: Lên 8 nhanh | J31: Aphelios | L31: Thợ Rèn Kiếm
B32: 3 | C32: S | D32: Sivir & Nidalee Nguyên Sinh | H32: Lên 8 nhanh | J32: Sivir | L32: Thợ Rèn Kiếm
B33: 4 | C33: A | D33: Kha'Zix Khắc Tinh (Thần Rừng Đao Phủ) | H33: Săn 3 sao 3 vàng (đổi tướng ở cấp 7) | J33: Kha'Zix | L33: Kiếm Tai Ương (Tạo Tác)
B34: 5 | C34: A | D34: Ahri & Morgana Thuật Sĩ | H34: Lên 8 nhanh | J34: Ahri | L34: Ấn Thuật Sĩ (lên S+)
B35: 6 | C35: A | D35: Ashe Hoa Linh Lên 9 | H35: Lên 9 nhanh | J35: Ashe | L35: Tinh Linh Hoàn Tiền (tốt nhất)
B36: 7 | C36: A | D36: Rồng Ngàn Tuổi Quái Rừng | H36: Lên 9 nhanh | J36: Rồng Ngàn Tuổi | L36: Thăng Cấp.
B37: 8 | C37: A | D37: Draven Lên 9 (Thần Rừng Đao Phủ) | H37: Lên 9 nhanh | J37: Draven | L37: Thăng Tiến Cuối Trận (+2 bậc)
B38: 9 | C38: B | D38: Caitlyn Dũng Sĩ Thợ Săn | H38: Săn 3 sao 2 vàng (đổi tướng từ từ ở cấp 6) | J38: Caitlyn | L38: Tăng Vốn I
B40: 10 NGUYÊN TẮC VÀNG ĐỂ VÀO TOP
B41: 01. Top 4 đều đặn quan trọng hơn thỉnh thoảng top 1. | I41: 02. Giữ mốc lãi 50 vàng – vàng là sức mạnh cuối game.
B42: 03. Chọn đội hình theo ĐỒ + LÕI, không theo sở thích. | I42: 04. Ghép đồ sớm, giữ máu, giữ chuỗi.
B43: 05. Đổi tướng đúng mốc: lên 8 nhanh thì dồn ở 4-2. | I43: 06. Xem bàn đối thủ mỗi vòng: né đội bị tranh.
B44: 07. Tinh Linh 0 vàng: gần như luôn mua. | I44: 08. Xếp vị trí chống người mạnh nhất.
B45: 09. Máu < 40: dồn tất cả vào sức mạnh ngay. | I45: 10. Sau mỗi ván: ghi lại 1 lỗi, sửa ở ván sau.
B47: CÓ GÌ MỚI · BẢN 18.4 (07/10/2026) + META VIỆT NAM HIỆN TẠI
B48: 🗓 Bản 18.4 – 07/10/2026 | E48: Bản 18.4 ra ngày 07/10/2026 (số liệu từ máy chủ thử nghiệm, có thể chỉnh nhẹ khi ra chính thức). Hiện tại máy chủ VN vẫn là 18.3b.
B49: ⚠ 18.4 giảm tướng | E49: Ashe: Năng Lượng khởi đầu 20 → 0 · Diana: Năng Lượng 30 → 40 · Maokai: Năng Lượng 90 → 100 · Master Yi: SMCK 62 → 60.
B50: ⚠ 18.4 giảm tộc/hệ | E50: Đao Phủ chảy máu (30/40% → 25/35%) · Dũng Sĩ 3 (45% → 42%) · Thợ Săn 4 (65% → 60%) · Hỏa Ngục 3/4 · Liên Kích 3/4 · Vệ Quân 6 (120 → 115) · Tiên Linh hồi máu · Mặt Trời 3 sao (15 → 12 Giáp/KP).
B51: ✅ 18.4 tăng tộc/hệ | E51: Thuật Sĩ hồi Năng Lượng mọi mốc (2/3/5 → 3/4/6) · Mặt Trăng Tốc Độ Đánh (10/14/18% → 12/16/20%) · Hoa Linh 3/4 (45/50% → 50/55%) · Tiên Hắc Ám nhiều Tinh Chất hơn · Quái Rừng 3 (5% → 6%) · Thiên Thực 8 giây · Mặt Trời 4 cần 7 tướng 3 sao (thay vì 8).
...

Sheet CHỌN ẤN → ĐỘI HÌNH
B2: 🌿 CHỌN ẤN → ĐỘI HÌNH MẠNH NHẤT | L2: v1.8 · 06/10/2026
B3: Chọn tối đa 3 Ấn bạn đang có + loại đồ → file tự xếp hạng 19 đội hình, chỉ rõ chủ lực, đỡ đòn, đồ và ai đeo Ấn nào | L3: Bản 18.3b · 18.4 ra 07/10
B4: ◄ Về Trang Chủ
B6: BƯỚC 1 – CHỌN ẤN BẠN ĐANG CÓ (từ lõi, Tinh Linh, vòng đi chợ hoặc tự ghép Xẻng / Chảo)
B7: Bấm ô vàng ▼ để chọn. Không có ấn thì để “— Không có —”. Chọn 2 ấn giống nhau = bạn có 2 ấn cùng loại. Ô cuối: loại đồ bạn đang cầm nhiều nhất.
B8: 🏳 Ấn thứ 1 | E8: Ấn Đao Phủ | I8: =IF(DATA_AN!$B$166=0,"",INDEX(DATA_AN!$C$2:$C$22,DATA_AN!$B$166)&" · "&INDEX(DATA_AN!$D$2:$D$22,DATA_AN!$B$166)) -> Chảo Vàng + Găng Đấu Tập · +20% Tỉ Lệ Chí Mạng, +8% Sát Thương Chí Mạng; kết liễu kẻ dưới 8% Máu
B9: 🏳 Ấn thứ 2 | E9: Ấn Mặt Trăng | I9: =IF(DATA_AN!$B$167=0,"",INDEX(DATA_AN!$C$2:$C$22,DATA_AN!$B$167)&" · "&INDEX(DATA_AN!$D$2:$D$22,DATA_AN!$B$167)) -> Xẻng Vàng + Nước Mắt Nữ Thần · +20% Tốc Độ Đánh, +3 Năng Lượng mỗi giây
B10: 🏳 Ấn thứ 3 | E10: — Không có — | I10: =IF(DATA_AN!$B$168=0,"",INDEX(DATA_AN!$C$2:$C$22,DATA_AN!$B$168)&" · "&INDEX(DATA_AN!$D$2:$D$22,DATA_AN!$B$168))
B11: ⚔ Đồ bạn đang có nghiêng về | E11: Chưa rõ / cân bằng | I11: Kiếm/Cung/Găng → ưu tiên đội chủ lực VẬT LÝ · Gậy/Nước Mắt → đội PHÉP · Giáp/Áo Choàng/Đai → đội cần đỡ đòn nhiều.
B13: KẾT QUẢ – ĐỘI HÌNH MẠNH NHẤT VỚI ẤN CỦA BẠN (tự cập nhật khi đổi lựa chọn)
B14: 🥇 TOP 1 | D14: =INDEX(DATA_AN!$M$2:$M$20,DATA_AN!$B$172) -> Đao Phủ Azir (Thực Vật · Tinh Nghịch) | L14: ="Điểm: "&TEXT(INDEX(DATA_AN!$AG$2:$AG$20,DATA_AN!$B$172),"0.0")&" (ấn +"&TEXT(INDEX(DATA_AN!$AH$2:$AH$20,DATA_AN!$B$172),"0.0")&")" -> Điểm: 12.9 (ấn +7.4)
D15: 📊 Số liệu | F15: =INDEX(DATA_AN!$Y$2:$Y$20,DATA_AN!$B$172)&" · "&INDEX(DATA_AN!$Z$2:$Z$20,DATA_AN!$B$172) -> VN 18.3b: hạng TB 2.69 · top 4 84,8% · 1,15% người chơi · ↘ 18.4: Đao Phủ chảy máu giảm (40% → 35%) – giảm NHẸ, vẫn là đội tốt nhất VN
D16: 👥 Đội hình đủ | F16: =INDEX(DATA_AN!$W$2:$W$20,DATA_AN!$B$172) -> Veigar, Teemo, Azir, Fiddlesticks, Rammus, Soraka, Zyra, Kennen
D17: 🌿 Tộc/hệ bật | F17: =INDEX(DATA_AN!$X$2:$X$20,DATA_AN!$B$172) -> 3 Tinh Nghịch · 3 Đao Phủ · 2 Gai Đen · 2 Thuật Sư · 2 Triệu Hồi · 2 Thực Vật · 2 Vệ Quân · 1 Vườn Gai
D18: ⚔ Chủ lực chính | F18: =INDEX(DATA_AN!$O$2:$O$20,DATA_AN!$B$172)&" · "&INDEX(DATA_AN!$P$2:$P$20,DATA_AN!$B$172)&" → "&INDEX(DATA_AN!$Q$2:$Q$20,DATA_AN!$B$172) -> Soraka · PHÉP → Găng Bảo Thạch · Nanh Nashor · Mũ Phù Thủy Rabadon
D19: 🏹 Chủ lực phụ | F19: =INDEX(DATA_AN!$R$2:$R$20,DATA_AN!$B$172)&" · "&INDEX(DATA_AN!$S$2:$S$20,DATA_AN!$B$172)&" → "&INDEX(DATA_AN!$T$2:$T$20,DATA_AN!$B$172) -> Zyra · PHÉP → Găng Bảo Thạch · Trượng Hư Vô · Ngọn Giáo Shojin
D20: 🛡 Đỡ đòn | F20: =INDEX(DATA_AN!$U$2:$U$20,DATA_AN!$B$172)&" → "&INDEX(DATA_AN!$V$2:$V$20,DATA_AN!$B$172) -> Rammus → Thú Tượng Thạch Giáp · Vương Miện Hoàng Gia · Áo Choàng Gai
D21: 🏳 Ấn 1 | F21: =IF(DATA_AN!$B$166=0,"— (không có ấn)",CHOOSE(DATA_AN!$C$166,INDEX(DATA_AN!$B$98:$V$116,DATA_AN!$B$172,DATA_AN!$B$166),INDEX(DATA_AN!$B$120:$V$138,DATA_AN!$B$172,DATA_AN!$B$166),INDEX(DATA_AN!$B$142:$V$160,DATA_AN!$B$172,DATA_AN!$B$166))&" · +"&TEXT(CHOOSE(DATA_AN!$C$166,INDEX(DATA_AN!$B$32:$V$50,DATA_AN!$B$172,DATA_AN!$B$166),INDEX(DATA_AN!$B$54:$V$72,DATA_AN!$B$172,DATA_AN!$B$166),INDEX(DATA_AN!$B$76:$V$94,DATA_AN!$B$172,DATA_AN!$B$166)),"0.0")&" điểm") -> Đeo cho Zyra · Đao Phủ 3 → 4 ✅ mở mốc 4 · +6.5 điểm
D22: 🏳 Ấn 2 | F22: =IF(AND(DATA_AN!$B$167>0,('CHỌN ẤN → ĐỘI HÌNH'!$E$8='CHỌN ẤN → ĐỘI HÌNH'!$E$9)>0),"↑ Cùng loại với ấn phía trên – đã tính chung, xem người đeo ở dòng trên",IF(DATA_AN!$B$167=0,"— (không có ấn)",CHOOSE(DATA_AN!$C$167,INDEX(DATA_AN!$B$98:$V$116,DATA_AN!$B$172,DATA_AN!$B$167),INDEX(DATA_AN!$B$120:$V$138,DATA_AN!$B$172,DATA_AN!$B$167),INDEX(DATA_AN!$B$142:$V$160,DATA_AN!$B$172,DATA_AN!$B$167))&" · +"&TEXT(CHOOSE(DATA_AN!$C$167,INDEX(DATA_AN!$B$32:$V$50,DATA_AN!$B$172,DATA_AN!$B$167),INDEX(DATA_AN!$B$54:$V$72,DATA_AN!$B$172,DATA_AN!$B$167),INDEX(DATA_AN!$B$76:$V$94,DATA_AN!$B$172,DATA_AN!$B$167)),"0.0")&" điểm")) -> Đeo cho Soraka · chưa có Mặt Trăng – chỉ lấy chỉ số của ấn (cần 1 Mặt Trăng nữa để mở mốc 2) · +0.9 điểm
D23: 🏳 Ấn 3 | F23: =IF(AND(DATA_AN!$B$168>0,('CHỌN ẤN → ĐỘI HÌNH'!$E$8='CHỌN ẤN → ĐỘI HÌNH'!$E$10)+('CHỌN ẤN → ĐỘI HÌNH'!$E$9='CHỌN ẤN → ĐỘI HÌNH'!$E$10)>0),"↑ Cùng loại với ấn phía trên – đã tính chung, xem người đeo ở dòng trên",IF(DATA_AN!$B$168=0,"— (không có ấn)",CHOOSE(DATA_AN!$C$168,INDEX(DATA_AN!$B$98:$V$116,DATA_AN!$B$172,DATA_AN!$B$168),INDEX(DATA_AN!$B$120:$V$138,DATA_AN!$B$172,DATA_AN!$B$168),INDEX(DATA_AN!$B$142:$V$160,DATA_AN!$B$172,DATA_AN!$B$168))&" · +"&TEXT(CHOOSE(DATA_AN!$C$168,INDEX(DATA_AN!$B$32:$V$50,DATA_AN!$B$172,DATA_AN!$B$168),INDEX(DATA_AN!$B$54:$V$72,DATA_AN!$B$172,DATA_AN!$B$168),INDEX(DATA_AN!$B$76:$V$94,DATA_AN!$B$172,DATA_AN!$B$168)),"0.0")&" điểm")) -> — (không có ấn)
D24: 📈 Lên cấp | F24: =INDEX(DATA_AN!$AA$2:$AA$20,DATA_AN!$B$172) -> Cấp 7 ở 3-5 → lên 8 ở 4-2 đổi tướng tìm Soraka + Zyra 2 sao → 9 thêm Malphite
D25: =HYPERLINK("#'CHỌN ẤN → ĐỘI HÌNH'!B"&INDEX(DATA_AN!$AB$2:$AB$20,DATA_AN!$B$172),"🖼 Xem hình tướng + đồ của đội này ▶") -> 🖼 Xem hình tướng + đồ của đội này ▶
B27: 🥈 TOP 2 | D27: =INDEX(DATA_AN!$M$2:$M$20,DATA_AN!$B$173) -> Thần Rừng Kha'Zix | L27: ="Điểm: "&TEXT(INDEX(DATA_AN!$AG$2:$AG$20,DATA_AN!$B$173),"0.0")&" (ấn +"&TEXT(INDEX(DATA_AN!$AH$2:$AH$20,DATA_AN!$B$173),"0.0")&")" -> Điểm: 12.5 (ấn +8.8)
D28: 📊 Số liệu | F28: =INDEX(DATA_AN!$Y$2:$Y$20,DATA_AN!$B$173)&" · "&INDEX(DATA_AN!$Z$2:$Z$20,DATA_AN!$B$173) -> VN 18.3b: hạng TB 3.09 · top 4 78,0% · 0,33% người chơi · → 18.4: Diana chậm hơn chút, Mặt Trăng (Aphelios) tăng – cân bằng
D29: 👥 Đội hình đủ | F29: =INDEX(DATA_AN!$W$2:$W$20,DATA_AN!$B$173) -> Ornn, Diana, Fiddlesticks, Hecarim, Kha'Zix, Aphelios, Ezreal, Soraka
D30: ⚔ Chủ lực chính | F30: =INDEX(DATA_AN!$O$2:$O$20,DATA_AN!$B$173)&" · "&INDEX(DATA_AN!$P$2:$P$20,DATA_AN!$B$173)&" → "&INDEX(DATA_AN!$Q$2:$Q$20,DATA_AN!$B$173) -> Kha'Zix · LAI (vật lý + phép) → Áo Choàng Bóng Tối · Bàn Tay Công Lý · Mũ Phù Thủy Rabadon
D31: 🏹 Chủ lực phụ | F31: =INDEX(DATA_AN!$R$2:$R$20,DATA_AN!$B$173)&" · "&INDEX(DATA_AN!$S$2:$S$20,DATA_AN!$B$173)&" → "&INDEX(DATA_AN!$T$2:$T$20,DATA_AN!$B$173) -> Aphelios · VẬT LÝ → Cuồng Đao Guinsoo · Vô Cực Kiếm · Thịnh Nộ Thủy Quái
D32: 🛡 Đỡ đòn | F32: =INDEX(DATA_AN!$U$2:$U$20,DATA_AN!$B$173)&" → "&INDEX(DATA_AN!$V$2:$V$20,DATA_AN!$B$173) -> Hecarim → Thú Tượng Thạch Giáp · Áo Choàng Lửa · Giáp Máu Warmog
D33: 🏳 Đeo ấn | F33: =IF(DATA_AN!$B$166=0,"","① "&IF(DATA_AN!$B$166=0,"— (không có ấn)",CHOOSE(DATA_AN!$C$166,INDEX(DATA_AN!$B$98:$V$116,DATA_AN!$B$173,DATA_AN!$B$166),INDEX(DATA_AN!$B$120:$V$138,DATA_AN!$B$173,DATA_AN!$B$166),INDEX(DATA_AN!$B$142:$V$160,DATA_AN!$B$173,DATA_AN!$B$166))&" · +"&TEXT(CHOOSE(DATA_AN!$C$166,INDEX(DATA_AN!$B$32:$V$50,DATA_AN!$B$173,DATA_AN!$B$166),INDEX(DATA_AN!$B$54:$V$72,DATA_AN!$B$173,DATA_AN!$B$166),INDEX(DATA_AN!$B$76:$V$94,DATA_AN!$B$173,DATA_AN!$B$166)),"0.0")&" điểm")&" ")&IF(DATA_AN!$B$167=0,"","② "&IF(AND(DATA_AN!$B$167>0,('CHỌN ẤN → ĐỘI HÌNH'!$E$8='CHỌN ẤN → ĐỘI HÌNH'!$E$9)>0),"↑ Cùng loại với ấn phía trên – đã tính chung, xem người đeo ở dòng trên",IF(DATA_AN!$B$167=0,"— (không có ấn)",CHOOSE(DATA_AN!$C$167,INDEX(DATA_AN!$B$98:$V$116,DATA_AN!$B$173,DATA_AN!$B$167),INDEX(DATA_AN!$B$120:$V$138,DATA_AN!$B$173,DATA_AN!$B$167),INDEX(DATA_AN!$B$142:$V$160,DATA_AN!$B$173,DATA_AN!$B$167))&" · +"&TEXT(CHOOSE(DATA_AN!$C$167,INDEX(DATA_AN!$B$32:$V$50,DATA_AN!$B$173,DATA_AN!$B$167),INDEX(DATA_AN!$B$54:$V$72,DATA_AN!$B$173,DATA_AN!$B$167),INDEX(DATA_AN!$B$76:$V$94,DATA_AN!$B$173,DATA_AN!$B$167)),"0.0")&" điểm"))&" ")&IF(DATA_AN!$B$168=0,"","③ "&IF(AND(DATA_AN!$B$168>0,('CHỌN ẤN → ĐỘI HÌNH'!$E$8='CHỌN ẤN → ĐỘI HÌNH'!$E$10)+('CHỌN ẤN → ĐỘI HÌNH'!$E$9='CHỌN ẤN → ĐỘI HÌNH'!$E$10)>0),"↑ Cùng loại với ấn phía trên – đã tính chung, xem người đeo ở dòng trên",IF(DATA_AN!$B$168=0,"— (không có ấn)",CHOOSE(DATA_AN!$C$168,INDEX(DATA_AN!$B$98:$V$116,DATA_AN!$B$173,DATA_AN!$B$168),INDEX(DATA_AN!$B$120:$V$138,DATA_AN!$B$173,DATA_AN!$B$168),INDEX(DATA_AN!$B$142:$V$160,DATA_AN!$B$173,DATA_AN!$B$168))&" · +"&TEXT(CHOOSE(DATA_AN!$C$168,INDEX(DATA_AN!$B$32:$V$50,DATA_AN!$B$173,DATA_AN!$B$168),INDEX(DATA_AN!$B$54:$V$72,DATA_AN!$B$173,DATA_AN!$B$168),INDEX(DATA_AN!$B$76:$V$94,DATA_AN!$B$173,DATA_AN!$B$168)),"0.0")&" điểm"))&" ") -> ① Đeo cho Kha'Zix · Đao Phủ 2 → 3 ✅ mở mốc 3 · +4.4 điểm ② Đeo cho Kha'Zix · Mặt Trăng 2 → 3 ✅ mở mốc 3 · +4.4 điểm
D34: =HYPERLINK("#'CHỌN ẤN → ĐỘI HÌNH'!B"&INDEX(DATA_AN!$AB$2:$AB$20,DATA_AN!$B$173),"🖼 Xem hình tướng + đồ của đội này ▶") -> 🖼 Xem hình tướng + đồ của đội này ▶
B36: 🥉 TOP 3 | D36: =INDEX(DATA_AN!$M$2:$M$20,DATA_AN!$B$174) -> Mặt Trăng Kayle (Mặt Trời) | L36: ="Điểm: "&TEXT(INDEX(DATA_AN!$AG$2:$AG$20,DATA_AN!$B$174),"0.0")&" (ấn +"&TEXT(INDEX(DATA_AN!$AH$2:$AH$20,DATA_AN!$B$174),"0.0")&")" -> Điểm: 9.9 (ấn +6.4)
D37: 📊 Số liệu | F37: =INDEX(DATA_AN!$Y$2:$Y$20,DATA_AN!$B$174)&" · "&INDEX(DATA_AN!$Z$2:$Z$20,DATA_AN!$B$174) -> VN 18.3b: hạng TB 2.67 · top 4 84,9% · 0,12% người chơi · ↗ 18.4: Mặt Trăng tăng, Mặt Trời dễ lên bậc 4 hơn (8 → 7) – MẠNH LÊN · mẫu số liệu nhỏ
D38: 👥 Đội hình đủ | F38: =INDEX(DATA_AN!$W$2:$W$20,DATA_AN!$B$174) -> Leona, Varus, Kayle, Sejuani, Shen, Diana, Aphelios, Alune
D39: ⚔ Chủ lực chính | F39: =INDEX(DATA_AN!$O$2:$O$20,DATA_AN!$B$174)&" · "&INDEX(DATA_AN!$P$2:$P$20,DATA_AN!$B$174)&" → "&INDEX(DATA_AN!$Q$2:$Q$20,DATA_AN!$B$174) -> Kayle · PHÉP → Cuồng Đao Guinsoo · Găng Bảo Thạch · Mũ Phù Thủy Rabadon
D40: 🏹 Chủ lực phụ | F40: =INDEX(DATA_AN!$R$2:$R$20,DATA_AN!$B$174)&" · "&INDEX(DATA_AN!$S$2:$S$20,DATA_AN!$B$174)&" → "&INDEX(DATA_AN!$T$2:$T$20,DATA_AN!$B$174) -> Aphelios · VẬT LÝ → Cuồng Đao Guinsoo · Vô Cực Kiếm · Kiếm Tử Thần
D41: 🛡 Đỡ đòn | F41: =INDEX(DATA_AN!$U$2:$U$20,DATA_AN!$B$174)&" → "&INDEX(DATA_AN!$V$2:$V$20,DATA_AN!$B$174) -> Sejuani → Thú Tượng Thạch Giáp · Giáp Tâm Linh · Giáp Máu Warmog
D42: 🏳 Đeo ấn | F42: =IF(DATA_AN!$B$166=0,"","① "&IF(DATA_AN!$B$166=0,"— (không có ấn)",CHOOSE(DATA_AN!$C$166,INDEX(DATA_AN!$B$98:$V$116,DATA_AN!$B$174,DATA_AN!$B$166),INDEX(DATA_AN!$B$120:$V$138,DATA_AN!$B$174,DATA_AN!$B$166),INDEX(DATA_AN!$B$142:$V$160,DATA_AN!$B$174,DATA_AN!$B$166))&" · +"&TEXT(CHOOSE(DATA_AN!$C$166,INDEX(DATA_AN!$B$32:$V$50,DATA_AN!$B$174,DATA_AN!$B$166),INDEX(DATA_AN!$B$54:$V$72,DATA_AN!$B$174,DATA_AN!$B$166),INDEX(DATA_AN!$B$76:$V$94,DATA_AN!$B$174,DATA_AN!$B$166)),"0.0")&" điểm")&" ")&IF(DATA_AN!$B$167=0,"","② "&IF(AND(DATA_AN!$B$167>0,('CHỌN ẤN → ĐỘI HÌNH'!$E$8='CHỌN ẤN → ĐỘI HÌNH'!$E$9)>0),"↑ Cùng loại với ấn phía trên – đã tính chung, xem người đeo ở dòng trên",IF(DATA_AN!$B$167=0,"— (không có ấn)",CHOOSE(DATA_AN!$C$167,INDEX(DATA_AN!$B$98:$V$116,DATA_AN!$B$174,DATA_AN!$B$167),INDEX(DATA_AN!$B$120:$V$138,DATA_AN!$B$174,DATA_AN!$B$167),INDEX(DATA_AN!$B$142:$V$160,DATA_AN!$B$174,DATA_AN!$B$167))&" · +"&TEXT(CHOOSE(DATA_AN!$C$167,INDEX(DATA_AN!$B$32:$V$50,DATA_AN!$B$174,DATA_AN!$B$167),INDEX(DATA_AN!$B$54:$V$72,DATA_AN!$B$174,DATA_AN!$B$167),INDEX(DATA_AN!$B$76:$V$94,DATA_AN!$B$174,DATA_AN!$B$167)),"0.0")&" điểm"))&" ")&IF(DATA_AN!$B$168=0,"","③ "&IF(AND(DATA_AN!$B$168>0,('CHỌN ẤN → ĐỘI HÌNH'!$E$8='CHỌN ẤN → ĐỘI HÌNH'!$E$10)+('CHỌN ẤN → ĐỘI HÌNH'!$E$9='CHỌN ẤN → ĐỘI HÌNH'!$E$10)>0),"↑ Cùng loại với ấn phía trên – đã tính chung, xem người đeo ở dòng trên",IF(DATA_AN!$B$168=0,"— (không có ấn)",CHOOSE(DATA_AN!$C$168,INDEX(DATA_AN!$B$98:$V$116,DATA_AN!$B$174,DATA_AN!$B$168),INDEX(DATA_AN!$B$120:$V$138,DATA_AN!$B$174,DATA_AN!$B$168),INDEX(DATA_AN!$B$142:$V$160,DATA_AN!$B$174,DATA_AN!$B$168))&" · +"&TEXT(CHOOSE(DATA_AN!$C$168,INDEX(DATA_AN!$B$32:$V$50,DATA_AN!$B$174,DATA_AN!$B$168),INDEX(DATA_AN!$B$54:$V$72,DATA_AN!$B$174,DATA_AN!$B$168),INDEX(DATA_AN!$B$76:$V$94,DATA_AN!$B$174,DATA_AN!$B$168)),"0.0")&" điểm"))&" ") -> ① Đeo cho Kayle · chưa có Đao Phủ – chỉ lấy chỉ số của ấn (cần 1 Đao Phủ nữa để mở mốc 2) · +0.9 điểm ② Đeo cho Kayle · Mặt Trăng 3 → 4 ✅ mở mốc 4 · +5.5 điểm
D43: =HYPERLINK("#'CHỌN ẤN → ĐỘI HÌNH'!B"&INDEX(DATA_AN!$AB$2:$AB$20,DATA_AN!$B$174),"🖼 Xem hình tướng + đồ của đội này ▶") -> 🖼 Xem hình tướng + đồ của đội này ▶
B45: Cách tính điểm: sức mạnh đội hình theo số liệu máy chủ VN (đã cân cỡ mẫu) + dự báo bản 18.4 + điểm từ Ấn (mở được mốc tộc/hệ = điểm lớn; chỉ cộng chỉ số = điểm nhỏ; ấn vô dụng ≈ 0) + loại đồ bạn đang cầm. Ấn gần như không giúp đội nào (điểm ấn ≈ 0–1) → cứ chơi đội mạnh nhất, coi ấn như món chỉ số.
B48: BẢNG XẾP HẠNG TẤT CẢ ĐỘI HÌNH VỚI ẤN ĐÃ CHỌN
...

Sheet LÕI → CÁCH ĐÁNH
B2: 🌿 LÕI → CÁCH ĐÁNH TỐI ƯU | L2: v1.8 · 06/10/2026
B3: Chọn lõi vừa nhận cho bạn cái gì (Vàng, Đồ, Ấn…) + bậc + vòng + máu → kế hoạch lên cấp, đổi tướng, đội hình hợp nhất | L3: Bản 18.3b · 18.4 ra 07/10
B4: ◄ Về Trang Chủ
B6: BƯỚC 1 – LÕI VỪA NHẬN
B7: Bấm các ô vàng ▼. Không chắc lõi thuộc loại nào? Xem cột 'Ví dụ lõi' ở bảng tóm tắt phía dưới.
B8: ✨ Lõi cho bạn cái gì? | F8: 💰 Vàng / Kinh tế
B9: 💎 Bậc lõi (màu khung) | F9: Vàng
B10: ⏱ Nhận ở vòng | F10: 2-1
B11: ❤ Máu hiện tại | F11: Trên 70 máu
B13: KẾ HOẠCH CHƠI CHO BẠN (tự đổi theo lựa chọn)
B14: 🎁 Bạn nhận được | E14: =INDEX(DATA_AN!$B$300:$B$308,MATCH($F$8,DATA_AN!$A$300:$A$308,0)) -> Vàng ngay hoặc vàng theo thời gian / lãi lớn hơn.
B15: 📋 Lõi loại này (xếp hạng) | E15: =INDEX(DATA_AN!$C$300:$C$308,MATCH($F$8,DATA_AN!$A$300:$A$308,0)) -> Kỷ Nguyên / Kỷ Nguyên+ (S) · Vượt Thời Gian / Định Hướng Tương Lai (S) · Kỳ Vọng Bất Ngờ (S) · Tăng Vốn I / II (A) · 🆕 18.4: lõi mới 'thua trận nhận 2 vàng + 1 lượt đổi miễn phí' (tên Việt chưa có)
B16: 💎 Theo bậc lõi | E16: =INDEX(DATA_AN!$J$300:$L$308,MATCH($F$8,DATA_AN!$A$300:$A$308,0),MATCH($F$9,DATA_AN!$A$320:$A$322,0)) -> Đủ để lên 8 ở 4-1 mà vẫn giữ trên 30 vàng – hướng 'lên 8 nhanh' chuẩn.
B17: ⏱ Theo vòng nhận | E17: =INDEX(DATA_AN!$M$300:$O$308,MATCH($F$8,DATA_AN!$A$300:$A$308,0),MATCH($F$10,DATA_AN!$A$324:$A$326,0)) -> Nhận sớm là mạnh nhất: giữ máu bằng tướng 2 sao rẻ, tích lãi tối đa tới Giai đoạn 4.
B18: ❤ Theo máu | E18: =VLOOKUP($F$11,DATA_AN!$A$328:$B$330,2,FALSE()) -> Có thể THAM: giữ lãi, chấp nhận thua chuỗi để đi đúng kế hoạch của lõi.
B19: 📈 Nhịp lên cấp | E19: =INDEX(DATA_AN!$D$300:$D$308,MATCH($F$8,DATA_AN!$A$300:$A$308,0)) -> Lên 8 sớm (3-5 hoặc 4-1) → lên 9 ở 5-1 nếu máu trên 50.
B20: 🎲 Đổi tướng | E20: =INDEX(DATA_AN!$E$300:$E$308,MATCH($F$8,DATA_AN!$A$300:$A$308,0)) -> KHÔNG đổi tướng trước 4-1. Giữ lãi 50 vàng mỗi vòng; dồn vàng 1 lần lớn ở cấp 8.
B21: 🔥 Chuỗi thắng / thua | E21: =INDEX(DATA_AN!$F$300:$F$308,MATCH($F$8,DATA_AN!$A$300:$A$308,0)) -> Chuỗi nào cũng được – đừng phá lãi chỉ để giữ chuỗi.
B22: 🏆 Đội hình hợp nhất | E22: =INDEX(DATA_AN!$G$300:$G$308,MATCH($F$8,DATA_AN!$A$300:$A$308,0)) -> Draven Dũng Sĩ Thần Rừng (lên 9) · Hoa Linh Ahri & Ashe (lên 9) · Quái Rừng thuần (Rồng Ngàn Tuổi)
B23: ✨ Lõi tiếp theo nên tìm | E23: =INDEX(DATA_AN!$H$300:$H$308,MATCH($F$8,DATA_AN!$A$300:$A$308,0)) -> 3-2: lõi Trang bị hoặc Ấn khớp chủ lực · 4-2: lõi Giao tranh.
B24: ⛔ Sai lầm cần tránh | E24: =INDEX(DATA_AN!$I$300:$I$308,MATCH($F$8,DATA_AN!$A$300:$A$308,0)) -> Đổi tướng ở Giai đoạn 3 (mất hết lợi thế vàng) · mua Tinh Linh làm tụt mốc lãi 10/20/30/40/50.
B25: 🖼 Xem hình đội hình | E25: =HYPERLINK("#'CHỌN ẤN → ĐỘI HÌNH'!B"&INDEX(DATA_AN!$P$300:$P$308,MATCH($F$8,DATA_AN!$A$300:$A$308,0)),"▶ "&INDEX(DATA_AN!$S$300:$S$308,MATCH($F$8,DATA_AN!$A$300:$A$308,0))) -> ▶ Draven Dũng Sĩ Thần Rừng (lên 9) | H25: =HYPERLINK("#'CHỌN ẤN → ĐỘI HÌNH'!B"&INDEX(DATA_AN!$Q$300:$Q$308,MATCH($F$8,DATA_AN!$A$300:$A$308,0)),"▶ "&INDEX(DATA_AN!$T$300:$T$308,MATCH($F$8,DATA_AN!$A$300:$A$308,0))) -> ▶ Hoa Linh Ahri & Ashe (lên 9) | K25: =HYPERLINK("#'CHỌN ẤN → ĐỘI HÌNH'!B"&INDEX(DATA_AN!$R$300:$R$308,MATCH($F$8,DATA_AN!$A$300:$A$308,0)),"▶ "&INDEX(DATA_AN!$U$300:$U$308,MATCH($F$8,DATA_AN!$A$300:$A$308,0))) -> ▶ Quái Rừng thuần (Rồng Ngàn Tuổi)
B26: ="👉 Lõi cho Ấn? Sang trang CHỌN ẤN → ĐỘI HÌNH để nhập ấn và xem chính xác ai đeo, mở mốc gì." -> 👉 Lõi cho Ấn? Sang trang CHỌN ẤN → ĐỘI HÌNH để nhập ấn và xem chính xác ai đeo, mở mốc gì.
B28: XẾP HẠNG LÕI TỘC HỆ (lõi gắn với 1 tộc/hệ) – bản 18.3b + thay đổi 18.4
B29: # | C29: Lõi | E29: Tộc/Hệ | F29: Sức mạnh | G29: Cho bạn | I29: Đội hình hợp | K29: Cách đánh | M29: Bản 18.4
C30: 1. Tinh Linh Hoàn Tiền / Tinh Linh Hoàn Tiền+ | E30: Hoa Linh | F30: S | G30: Hoàn vàng khi mua Tinh Linh | I30: Hoa Linh Ahri & Ashe | K30: Mua MỌI Tinh Linh, lên 9 nhanh | M30: ↗ Hoa Linh 3/4 tăng
C31: 2. Tiếng Gọi Hoa Linh | E31: Hoa Linh | F31: S | G31: Cường hoá tộc Hoa Linh / Tinh Linh | I31: Hoa Linh Ahri & Ashe | K31: Ra sân 5 Hoa Linh, lên 9 | M31: ↗ Hoa Linh tăng
C32: 3. Thực Vật Hấp Thụ | E32: Thực Vật | F32: S (1 người/phòng) | G32: Cường hoá tộc Thực Vật | I32: Đao Phủ Azir / Thuật Sư Veigar | K32: Đi Đao Phủ Azir – đội tốt nhất VN | M32: ↘ Đao Phủ giảm nhẹ
C33: 4. Quái Thú Bên Trong (Nidalee / Sivir) | E33: Nguyên Sinh | F33: S | G33: Biến Nidalee hoặc Sivir thành chủ lực siêu mạnh | I33: Mặt Trăng Nidalee / Thợ Săn Sivir | K33: Ép tướng được chọn lên 2 sao, dồn đồ | M33: ↗ Nidalee (Mặt Trăng tăng) · ↘ Sivir (Thợ Săn giảm)
C34: 5. Phân Nhánh / Phân Nhánh+ | E34: Mọi tộc | F34: S | G34: 1 Ấn ngẫu nhiên (+ công cụ đổi) | I34: Theo Ấn → trang CHỌN ẤN | K34: Nhập Ấn vào trang CHỌN ẤN | M34: →
C35: 6. Cắm Rễ Phân Tán | E35: Thần Rừng / Ấn | F35: S | G35: Thêm Ấn / tộc | I35: Thần Rừng Kha'Zix / Ezreal | K35: Đẩy Thần Rừng lên mốc cao | M35: →
C36: 7. Quái Rừng Omega | E36: Quái Rừng | F36: A → S | G36: Cường hoá Quái Rừng Đầu Đàn | I36: Quái Rừng thuần (Rồng Ngàn Tuổi) | K36: Ra sân 6–7 Quái Rừng, lên 9 | M36: ↑ 18.4: +15% Máu, +12% Tốc Độ Đánh
C37: 8. Tín Đồ Tiên Hắc Ám | E37: Tiên Hắc Ám | F37: A (1 người/phòng) | G37: Đổi Tinh Chất lấy quà lớn | I37: Tiên Phong Alune / Tiên Hắc Ám | K37: Thua đầu game tích Tinh Chất | M37: ↗ 18.4: nhận Tinh Chất nhiều hơn
C38: 9. Tà Thuật | E38: Tiên Hắc Ám | F38: ⚠ kiểm tra | G38: Tinh Chất → SMPT | I38: Tiên Hắc Ám Cassiopeia | K38: Bị TẮT ở 18.3b – xem trong game đã bật lại chưa | M38: ?
C39: 10. Tôi Thăng Cấp Một Mình | E39: Khắc Tinh | F39: S (có điều kiện) | G39: Rengar gánh một mình | I39: Thích Ứng Rengar | K39: Săn Rengar 3 sao | M39: ↘ Yi giảm nhẹ
C40: 11. Không Đối Thủ | E40: Khắc Tinh | F40: Mở khoá | G40: Ra sân cả Kha'Zix + Rengar | I40: Thần Rừng Kha'Zix | K40: Thêm Rengar làm chủ lực phụ | M40: →
C41: 12. Sơ Đồ Tuyến Sau | E41: Tướng + Ấn | F41: A | G41: Tướng 3 vàng hàng sau + Ấn của nó | I41: Linh hoạt | K41: Xây đội quanh tướng nhận được | M41: →
B43: BẢNG TÓM TẮT – 9 LOẠI LÕI VÀ CÁCH ĐÁNH
B44: Loại lõi | D44: Ví dụ lõi (xếp hạng) | H44: Nhịp lên cấp | K44: Đội hình hợp nhất
B45: 💰 Vàng / Kinh tế | D45: Kỷ Nguyên / Kỷ Nguyên+ (S) · Vượt Thời Gian / Định Hướng Tương Lai (S) · Kỳ Vọng Bất Ngờ (S) · Tăng Vốn I / II (A) · 🆕 18.4: lõi mới 'thua trận nhận 2 vàng + 1 lượt đổi miễn phí' (tên Việt chưa có) | H45: Lên 8 sớm (3-5 hoặc 4-1) → lên 9 ở 5-1 nếu máu trên 50. | K45: Draven Dũng Sĩ Thần Rừng (lên 9) · Hoa Linh Ahri & Ashe (lên 9) · Quái Rừng thuần (Rồng Ngàn Tuổi)
...

Sheet CHỌN ĐỘI HÌNH
B2: 🌿 CHỌN ĐỘI HÌNH MẠNH | L2: v1.8 · 06/10/2026
B3: Bấm ô vàng → chọn đội hình → lộ trình, lên đồ, xếp vị trí tự hiện ra | L3: Bản 18.3b · 18.4 ra 07/10
B4: ◄ Về Trang Chủ
B6: ① CHỌN ĐỘI HÌNH ▶ | E6: Đao Phủ Azir – Soraka & Zyra (Thực Vật) | K6: =HYPERLINK("#'HÌNH ẢNH ĐỘI HÌNH'!B"&INDEX(DATA!$AQ$2:$AQ$20,MATCH($E$6,DATA!$A$2:$A$20,0)),"🖼 Xem HÌNH ẢNH đội hình này ▶") -> 🖼 Xem HÌNH ẢNH đội hình này ▶
B8: HẠNG | D8: LỐI CHƠI | G8: ĐỘ KHÓ | I8: NHÓM TƯỚNG CHỦ LỰC | K8: THỨ HẠNG HIỆN TẠI
B9: =INDEX(DATA!$B$2:$B$20,MATCH($E$6,DATA!$A$2:$A$20,0)) -> S | D9: =INDEX(DATA!$C$2:$C$20,MATCH($E$6,DATA!$A$2:$A$20,0)) -> Lên 8 nhanh | G9: =INDEX(DATA!$D$2:$D$20,MATCH($E$6,DATA!$A$2:$A$20,0)) -> Trung bình | I9: =INDEX(DATA!$E$2:$E$20,MATCH($E$6,DATA!$A$2:$A$20,0)) -> 4 vàng | K9: ="#"&INDEX(DATA!$F$2:$F$20,MATCH($E$6,DATA!$A$2:$A$20,0))&" / 19" -> #1 / 19
B11: TỔNG QUAN
B12: =INDEX(DATA!$H$2:$H$20,MATCH($E$6,DATA!$A$2:$A$20,0)) -> ĐỘI TỐT NHẤT MÁY CHỦ VN (18.3b: hạng TB 2.69, top 4 84,8%). Soraka + Zyra gây sát thương phép có chí mạng (Đao Phủ); Azir triệu hồi lính; Veigar + Teemo + Rammus bật Tinh Nghịch cho Rammus cưỡi Bạn Lông Xù làm tường thịt; Fiddlesticks hồi máu (Thực Vật).
B13: Tộc / Hệ kích hoạt | E13: =INDEX(DATA!$G$2:$G$20,MATCH($E$6,DATA!$A$2:$A$20,0)) -> 4 Đao Phủ (có Ấn) · 3 Tinh Nghịch · 2 Thực Vật · 2 Triệu Hồi · 2 Gai Đen · 2 Thuật Sư · 2 Vệ Quân · Vườn Gai
B15: LỘ TRÌNH TRẬN ĐẤU
B16: 📈 Lên cấp & đổi tướng | E16: =INDEX(DATA!$I$2:$I$20,MATCH($E$6,DATA!$A$2:$A$20,0)) -> Cấp 7 ở 3-5 → lên 8 ở 4-2, đổi tướng tìm Soraka + Zyra 2 sao → lên 9 thêm Malphite.
B17: 🌱 Mở màn (Giai đoạn 2) | E17: =INDEX(DATA!$J$2:$J$20,MATCH($E$6,DATA!$A$2:$A$20,0)) -> Mở đầu đội phép rẻ: Veigar, Teemo, Rek'Sai/Kobuko. Ghép sớm Găng Bảo Thạch / Nanh Nashor cho Veigar làm chủ lực tạm.
B18: ⚙️ Giữa trận (Giai đoạn 3–4) | E18: =INDEX(DATA!$K$2:$K$20,MATCH($E$6,DATA!$A$2:$A$20,0)) -> Cấp 7: Veigar, Teemo, Azir, Fiddlesticks, Rammus, Kennen/Zyra + chủ lực tạm. Rammus cưỡi Bạn Lông Xù.
B20: ĐỘI HÌNH CUỐI (CẤP 8 – 9)
B21: # | C21: Tướng | F21: Giá | G21: Tộc / Hệ | L21: Vai trò trong đội
B22: 1 | C22: =IF(INDEX(DATA!$L$2:$L$20,MATCH($E$6,DATA!$A$2:$A$20,0))="","",INDEX(DATA!$L$2:$L$20,MATCH($E$6,DATA!$A$2:$A$20,0))) -> Veigar | F22: =IF(C22="","",INDEX(DATA!$BA$2:$BA$66,MATCH(C22,DATA!$AZ$2:$AZ$66,0))) -> 1 | G22: =IF(C22="","",INDEX(DATA!$BB$2:$BB$66,MATCH(C22,DATA!$AZ$2:$AZ$66,0))) -> Gai Đen, Tinh Nghịch, Thuật Sư | L22: =IF(C22="","",IF(C22=INDEX(DATA!$U$2:$U$20,MATCH($E$6,DATA!$A$2:$A$20,0)),"⚔ CHỦ LỰC CHÍNH",IF(C22=INDEX(DATA!$Z$2:$Z$20,MATCH($E$6,DATA!$A$2:$A$20,0)),"🏹 CHỦ LỰC PHỤ",IF(C22=INDEX(DATA!$AE$2:$AE$20,MATCH($E$6,DATA!$A$2:$A$20,0)),"🛡 ĐỠ ĐÒN CHÍNH","Hỗ trợ / kích tộc")))) -> Hỗ trợ / kích tộc
B23: 2 | C23: =IF(INDEX(DATA!$M$2:$M$20,MATCH($E$6,DATA!$A$2:$A$20,0))="","",INDEX(DATA!$M$2:$M$20,MATCH($E$6,DATA!$A$2:$A$20,0))) -> Teemo | F23: =IF(C23="","",INDEX(DATA!$BA$2:$BA$66,MATCH(C23,DATA!$AZ$2:$AZ$66,0))) -> 2 | G23: =IF(C23="","",INDEX(DATA!$BB$2:$BB$66,MATCH(C23,DATA!$AZ$2:$AZ$66,0))) -> Tinh Nghịch, Thuật Sĩ | L23: =IF(C23="","",IF(C23=INDEX(DATA!$U$2:$U$20,MATCH($E$6,DATA!$A$2:$A$20,0)),"⚔ CHỦ LỰC CHÍNH",IF(C23=INDEX(DATA!$Z$2:$Z$20,MATCH($E$6,DATA!$A$2:$A$20,0)),"🏹 CHỦ LỰC PHỤ",IF(C23=INDEX(DATA!$AE$2:$AE$20,MATCH($E$6,DATA!$A$2:$A$20,0)),"🛡 ĐỠ ĐÒN CHÍNH","Hỗ trợ / kích tộc")))) -> Hỗ trợ / kích tộc
B24: 3 | C24: =IF(INDEX(DATA!$N$2:$N$20,MATCH($E$6,DATA!$A$2:$A$20,0))="","",INDEX(DATA!$N$2:$N$20,MATCH($E$6,DATA!$A$2:$A$20,0))) -> Azir | F24: =IF(C24="","",INDEX(DATA!$BA$2:$BA$66,MATCH(C24,DATA!$AZ$2:$AZ$66,0))) -> 3 | G24: =IF(C24="","",INDEX(DATA!$BB$2:$BB$66,MATCH(C24,DATA!$AZ$2:$AZ$66,0))) -> Gai Đen, Đao Phủ, Triệu Hồi | L24: =IF(C24="","",IF(C24=INDEX(DATA!$U$2:$U$20,MATCH($E$6,DATA!$A$2:$A$20,0)),"⚔ CHỦ LỰC CHÍNH",IF(C24=INDEX(DATA!$Z$2:$Z$20,MATCH($E$6,DATA!$A$2:$A$20,0)),"🏹 CHỦ LỰC PHỤ",IF(C24=INDEX(DATA!$AE$2:$AE$20,MATCH($E$6,DATA!$A$2:$A$20,0)),"🛡 ĐỠ ĐÒN CHÍNH","Hỗ trợ / kích tộc")))) -> Hỗ trợ / kích tộc
B25: 4 | C25: =IF(INDEX(DATA!$O$2:$O$20,MATCH($E$6,DATA!$A$2:$A$20,0))="","",INDEX(DATA!$O$2:$O$20,MATCH($E$6,DATA!$A$2:$A$20,0))) -> Fiddlesticks | F25: =IF(C25="","",INDEX(DATA!$BA$2:$BA$66,MATCH(C25,DATA!$AZ$2:$AZ$66,0))) -> 3 | G25: =IF(C25="","",INDEX(DATA!$BB$2:$BB$66,MATCH(C25,DATA!$AZ$2:$AZ$66,0))) -> Thực Vật, Vệ Quân, Thuật Sư | L25: =IF(C25="","",IF(C25=INDEX(DATA!$U$2:$U$20,MATCH($E$6,DATA!$A$2:$A$20,0)),"⚔ CHỦ LỰC CHÍNH",IF(C25=INDEX(DATA!$Z$2:$Z$20,MATCH($E$6,DATA!$A$2:$A$20,0)),"🏹 CHỦ LỰC PHỤ",IF(C25=INDEX(DATA!$AE$2:$AE$20,MATCH($E$6,DATA!$A$2:$A$20,0)),"🛡 ĐỠ ĐÒN CHÍNH","Hỗ trợ / kích tộc")))) -> Hỗ trợ / kích tộc
B26: 5 | C26: =IF(INDEX(DATA!$P$2:$P$20,MATCH($E$6,DATA!$A$2:$A$20,0))="","",INDEX(DATA!$P$2:$P$20,MATCH($E$6,DATA!$A$2:$A$20,0))) -> Rammus | F26: =IF(C26="","",INDEX(DATA!$BA$2:$BA$66,MATCH(C26,DATA!$AZ$2:$AZ$66,0))) -> 3 | G26: =IF(C26="","",INDEX(DATA!$BB$2:$BB$66,MATCH(C26,DATA!$AZ$2:$AZ$66,0))) -> Tinh Nghịch, Vệ Quân | L26: =IF(C26="","",IF(C26=INDEX(DATA!$U$2:$U$20,MATCH($E$6,DATA!$A$2:$A$20,0)),"⚔ CHỦ LỰC CHÍNH",IF(C26=INDEX(DATA!$Z$2:$Z$20,MATCH($E$6,DATA!$A$2:$A$20,0)),"🏹 CHỦ LỰC PHỤ",IF(C26=INDEX(DATA!$AE$2:$AE$20,MATCH($E$6,DATA!$A$2:$A$20,0)),"🛡 ĐỠ ĐÒN CHÍNH","Hỗ trợ / kích tộc")))) -> 🛡 ĐỠ ĐÒN CHÍNH
B27: 6 | C27: =IF(INDEX(DATA!$Q$2:$Q$20,MATCH($E$6,DATA!$A$2:$A$20,0))="","",INDEX(DATA!$Q$2:$Q$20,MATCH($E$6,DATA!$A$2:$A$20,0))) -> Soraka | F27: =IF(C27="","",INDEX(DATA!$BA$2:$BA$66,MATCH(C27,DATA!$AZ$2:$AZ$66,0))) -> 4 | G27: =IF(C27="","",INDEX(DATA!$BB$2:$BB$66,MATCH(C27,DATA!$AZ$2:$AZ$66,0))) -> Thực Vật, Đao Phủ | L27: =IF(C27="","",IF(C27=INDEX(DATA!$U$2:$U$20,MATCH($E$6,DATA!$A$2:$A$20,0)),"⚔ CHỦ LỰC CHÍNH",IF(C27=INDEX(DATA!$Z$2:$Z$20,MATCH($E$6,DATA!$A$2:$A$20,0)),"🏹 CHỦ LỰC PHỤ",IF(C27=INDEX(DATA!$AE$2:$AE$20,MATCH($E$6,DATA!$A$2:$A$20,0)),"🛡 ĐỠ ĐÒN CHÍNH","Hỗ trợ / kích tộc")))) -> ⚔ CHỦ LỰC CHÍNH
B28: 7 | C28: =IF(INDEX(DATA!$R$2:$R$20,MATCH($E$6,DATA!$A$2:$A$20,0))="","",INDEX(DATA!$R$2:$R$20,MATCH($E$6,DATA!$A$2:$A$20,0))) -> Zyra | F28: =IF(C28="","",INDEX(DATA!$BA$2:$BA$66,MATCH(C28,DATA!$AZ$2:$AZ$66,0))) -> 4 | G28: =IF(C28="","",INDEX(DATA!$BB$2:$BB$66,MATCH(C28,DATA!$AZ$2:$AZ$66,0))) -> Vườn Gai, Triệu Hồi | L28: =IF(C28="","",IF(C28=INDEX(DATA!$U$2:$U$20,MATCH($E$6,DATA!$A$2:$A$20,0)),"⚔ CHỦ LỰC CHÍNH",IF(C28=INDEX(DATA!$Z$2:$Z$20,MATCH($E$6,DATA!$A$2:$A$20,0)),"🏹 CHỦ LỰC PHỤ",IF(C28=INDEX(DATA!$AE$2:$AE$20,MATCH($E$6,DATA!$A$2:$A$20,0)),"🛡 ĐỠ ĐÒN CHÍNH","Hỗ trợ / kích tộc")))) -> 🏹 CHỦ LỰC PHỤ
B29: 8 | C29: =IF(INDEX(DATA!$S$2:$S$20,MATCH($E$6,DATA!$A$2:$A$20,0))="","",INDEX(DATA!$S$2:$S$20,MATCH($E$6,DATA!$A$2:$A$20,0))) -> Kennen | F29: =IF(C29="","",INDEX(DATA!$BA$2:$BA$66,MATCH(C29,DATA!$AZ$2:$AZ$66,0))) -> 5 | G29: =IF(C29="","",INDEX(DATA!$BB$2:$BB$66,MATCH(C29,DATA!$AZ$2:$AZ$66,0))) -> Hỏa Ngục, Đao Phủ | L29: =IF(C29="","",IF(C29=INDEX(DATA!$U$2:$U$20,MATCH($E$6,DATA!$A$2:$A$20,0)),"⚔ CHỦ LỰC CHÍNH",IF(C29=INDEX(DATA!$Z$2:$Z$20,MATCH($E$6,DATA!$A$2:$A$20,0)),"🏹 CHỦ LỰC PHỤ",IF(C29=INDEX(DATA!$AE$2:$AE$20,MATCH($E$6,DATA!$A$2:$A$20,0)),"🛡 ĐỠ ĐÒN CHÍNH","Hỗ trợ / kích tộc")))) -> Hỗ trợ / kích tộc
B30: 9 | C30: =IF(INDEX(DATA!$T$2:$T$20,MATCH($E$6,DATA!$A$2:$A$20,0))="","",INDEX(DATA!$T$2:$T$20,MATCH($E$6,DATA!$A$2:$A$20,0))) -> Malphite | F30: =IF(C30="","",INDEX(DATA!$BA$2:$BA$66,MATCH(C30,DATA!$AZ$2:$AZ$66,0))) -> 4 | G30: =IF(C30="","",INDEX(DATA!$BB$2:$BB$66,MATCH(C30,DATA!$AZ$2:$AZ$66,0))) -> Gai Đen, Cự Thạch | L30: =IF(C30="","",IF(C30=INDEX(DATA!$U$2:$U$20,MATCH($E$6,DATA!$A$2:$A$20,0)),"⚔ CHỦ LỰC CHÍNH",IF(C30=INDEX(DATA!$Z$2:$Z$20,MATCH($E$6,DATA!$A$2:$A$20,0)),"🏹 CHỦ LỰC PHỤ",IF(C30=INDEX(DATA!$AE$2:$AE$20,MATCH($E$6,DATA!$A$2:$A$20,0)),"🛡 ĐỠ ĐÒN CHÍNH","Hỗ trợ / kích tộc")))) -> Hỗ trợ / kích tộc
B32: LÊN ĐỒ CHUẨN · dòng chữ nhỏ = công thức ghép
B33: Vai trò | D33: Tướng | F33: Món 1 | H33: Món 2 | J33: Món 3 | L33: Thay thế / Tạo Tác
B34: ⚔ Chủ lực chính | D34: =INDEX(DATA!$U$2:$U$20,MATCH($E$6,DATA!$A$2:$A$20,0)) -> Soraka | F34: =INDEX(DATA!$V$2:$V$20,MATCH($E$6,DATA!$A$2:$A$20,0)) -> Găng Bảo Thạch | H34: =INDEX(DATA!$W$2:$W$20,MATCH($E$6,DATA!$A$2:$A$20,0)) -> Nanh Nashor | J34: =INDEX(DATA!$X$2:$X$20,MATCH($E$6,DATA!$A$2:$A$20,0)) -> Mũ Phù Thủy Rabadon | L34: =INDEX(DATA!$Y$2:$Y$20,MATCH($E$6,DATA!$A$2:$A$20,0)) -> Mũ Thích Nghi thay Rabadon · Tạo Tác: Lõi Bình Minh, Kiếm Tai Ương
F35: =IFERROR(INDEX(DATA!$BK$2:$BK$46,MATCH(F34,DATA!$BF$2:$BF$46,0)),"") -> Gậy Quá Khổ + Găng Đấu Tập | H35: =IFERROR(INDEX(DATA!$BK$2:$BK$46,MATCH(H34,DATA!$BF$2:$BF$46,0)),"") -> Cung Gỗ + Đai Khổng Lồ | J35: =IFERROR(INDEX(DATA!$BK$2:$BK$46,MATCH(J34,DATA!$BF$2:$BF$46,0)),"") -> Gậy Quá Khổ + Gậy Quá Khổ
B36: 🏹 Chủ lực phụ | D36: =INDEX(DATA!$Z$2:$Z$20,MATCH($E$6,DATA!$A$2:$A$20,0)) -> Zyra | F36: =INDEX(DATA!$AA$2:$AA$20,MATCH($E$6,DATA!$A$2:$A$20,0)) -> Găng Bảo Thạch | H36: =INDEX(DATA!$AB$2:$AB$20,MATCH($E$6,DATA!$A$2:$A$20,0)) -> Trượng Hư Vô | J36: =INDEX(DATA!$AC$2:$AC$20,MATCH($E$6,DATA!$A$2:$A$20,0)) -> Ngọn Giáo Shojin | L36: =INDEX(DATA!$AD$2:$AD$20,MATCH($E$6,DATA!$A$2:$A$20,0)) -> Ấn Đao Phủ đeo cho Zyra = mở Đao Phủ 4 (tốt nhất)
F37: =IFERROR(INDEX(DATA!$BK$2:$BK$46,MATCH(F36,DATA!$BF$2:$BF$46,0)),"") -> Gậy Quá Khổ + Găng Đấu Tập | H37: =IFERROR(INDEX(DATA!$BK$2:$BK$46,MATCH(H36,DATA!$BF$2:$BF$46,0)),"") -> Cung Gỗ + Nước Mắt Nữ Thần | J37: =IFERROR(INDEX(DATA!$BK$2:$BK$46,MATCH(J36,DATA!$BF$2:$BF$46,0)),"") -> Kiếm BF + Nước Mắt Nữ Thần
B38: 🛡 Đỡ đòn chính | D38: =INDEX(DATA!$AE$2:$AE$20,MATCH($E$6,DATA!$A$2:$A$20,0)) -> Rammus | F38: =INDEX(DATA!$AF$2:$AF$20,MATCH($E$6,DATA!$A$2:$A$20,0)) -> Thú Tượng Thạch Giáp | H38: =INDEX(DATA!$AG$2:$AG$20,MATCH($E$6,DATA!$A$2:$A$20,0)) -> Vương Miện Hoàng Gia | J38: =INDEX(DATA!$AH$2:$AH$20,MATCH($E$6,DATA!$A$2:$A$20,0)) -> Áo Choàng Gai | L38: =INDEX(DATA!$AI$2:$AI$20,MATCH($E$6,DATA!$A$2:$A$20,0)) -> Fiddlesticks: Nỏ Sét / Áo Choàng Lửa · Malphite (cấp 9): Giáp Máu Warmog
F39: =IFERROR(INDEX(DATA!$BK$2:$BK$46,MATCH(F38,DATA!$BF$2:$BF$46,0)),"") -> Giáp Lưới + Áo Choàng Bạc | H39: =IFERROR(INDEX(DATA!$BK$2:$BK$46,MATCH(H38,DATA!$BF$2:$BF$46,0)),"") -> Gậy Quá Khổ + Giáp Lưới | J39: =IFERROR(INDEX(DATA!$BK$2:$BK$46,MATCH(J38,DATA!$BF$2:$BF$46,0)),"") -> Giáp Lưới + Giáp Lưới
B41: 🔧 Ưu tiên mảnh đồ | E41: =INDEX(DATA!$AJ$2:$AJ$20,MATCH($E$6,DATA!$A$2:$A$20,0)) -> Gậy Quá Khổ > Găng Đấu Tập > Nước Mắt Nữ Thần > Giáp Lưới > Áo Choàng Bạc
B42: ✨ Lõi nâng cấp khuyên dùng | E42: =INDEX(DATA!$AK$2:$AK$20,MATCH($E$6,DATA!$A$2:$A$20,0)) -> Thực Vật Hấp Thụ, Khiên Đơn Đấu, Đam Mê Gậy, Giữ Vững Hàng Ngũ, Ấn Đao Phủ
B43: 🎯 Khi nào nên chơi | E43: =INDEX(DATA!$AL$2:$AL$20,MATCH($E$6,DATA!$A$2:$A$20,0)) -> Có đồ phép + Găng; ít đội phép khác trong phòng. ⚠ 18.4 (07/10): Đao Phủ chảy máu giảm nhẹ (40% → 35%) – vẫn rất mạnh.
B45: TRIỂN KHAI & XẾP VỊ TRÍ
B46: 🗺 Xếp vị trí | E46: =INDEX(DATA!$AM$2:$AM$20,MATCH($E$6,DATA!$A$2:$A$20,0)) -> Soraka & Zyra hàng sau ở 2 góc; Rammus (cưỡi Bạn Lông Xù) + Fiddlesticks hàng đầu giữa; cây của Zyra lấp khoảng trống phía trước.
B47: 💡 Mẹo leo hạng | E47: =INDEX(DATA!$AN$2:$AN$20,MATCH($E$6,DATA!$A$2:$A$20,0)) -> Đây là đội Azir + Rammus + Teemo + Fiddlesticks + Veigar + Zyra + Soraka – số liệu VN xác nhận mạnh nhất · Ấn Đao Phủ → Zyra · Ấn Thuật Sĩ → Soraka · Giữ từ 6 cây Zyra sống để Vườn Gai lên 10%.
B48: ⚠️ Điểm yếu / khắc chế | E48: =INDEX(DATA!$AO$2:$AO$20,MATCH($E$6,DATA!$A$2:$A$20,0)) -> Đội dồn sát thương phép nhanh; Soraka bị bắt sớm; 2 người cùng ép Soraka/Zyra.
B50: Mẫu bàn cờ gợi ý | E50: =INDEX(DATA!$AP$2:$AP$20,MATCH($E$6,DATA!$A$2:$A$20,0)) -> Chủ lực ở góc (chuẩn)
...

Sheet HÌNH ẢNH ĐỘI HÌNH
B2: 🌿 HÌNH ẢNH ĐỘI HÌNH | L2: v1.8 · 06/10/2026
B3: Nhìn hình để nhận biết tướng, trang bị và lõi của các đội hình mạnh – bấm tên đội ở trang XẾP HẠNG để nhảy tới | L3: Bản 18.3b · 18.4 ra 07/10
B4: ◄ Về Trang Chủ
B7: S | C7: #1 Đao Phủ Azir – Soraka & Zyra (Thực Vật) | K7: Lên 8 nhanh · Trung bình
B8: ĐỘI HÌNH CUỐI | L8: ⚔ chủ lực chính · 🏹 chủ lực phụ · 🛡 đỡ đòn chính Màu ô tên = giá tướng (xám 1 · xanh lá 2 · xanh dương 3 · tím 4 · vàng 5) Tộc/Hệ: 4 Đao Phủ (có Ấn) · 3 Tinh Nghịch · 2 Thực Vật · 2 Triệu Hồi · 2 Gai Đen · 2 Thuật Sư · 2 Vệ Quân · Vườn Gai
C9: Veigar | D9: Teemo | E9: Azir | F9: Fiddlesticks | G9: 🛡 Rammus | H9: ⚔ Soraka | I9: 🏹 Zyra | J9: Kennen | K9: Malphite
B10: ⚔ Chủ lực chính | D10: Soraka | F10: Găng Bảo Thạch | H10: Nanh Nashor | J10: Mũ Phù Thủy Rabadon | K10: Mũ Thích Nghi thay Rabadon · Tạo Tác: Lõi Bình Minh, Kiếm Tai Ương
B11: 🏹 Chủ lực phụ | D11: Zyra | F11: Găng Bảo Thạch | H11: Trượng Hư Vô | J11: Ngọn Giáo Shojin | K11: Ấn Đao Phủ đeo cho Zyra = mở Đao Phủ 4 (tốt nhất)
B12: 🛡 Đỡ đòn chính | D12: Rammus | F12: Thú Tượng Thạch Giáp | H12: Vương Miện Hoàng Gia | J12: Áo Choàng Gai | K12: Fiddlesticks: Nỏ Sét / Áo Choàng Lửa · Malphite (cấp 9): Giáp Máu Warmog
B13: ✨ Lõi nên chọn | D13: Thực Vật Hấp Thụ | F13: Khiên Đơn Đấu | H13: Đam Mê Gậy | J13: Giữ Vững Hàng Ngũ | K13: Khác: Ấn Đao Phủ
B15: S | C15: #2 Nidalee & Aphelios Mặt Trăng | K15: Lên 8 nhanh · Trung bình
B16: ĐỘI HÌNH CUỐI | L16: ⚔ chủ lực chính · 🏹 chủ lực phụ · 🛡 đỡ đòn chính Màu ô tên = giá tướng (xám 1 · xanh lá 2 · xanh dương 3 · tím 4 · vàng 5) Tộc/Hệ: 2 Mặt Trăng · 2 Liên Kích · 2 Nguyên Sinh · 2 Thích Ứng · 2 Dũng Sĩ · 2 Tiên Phong · 2 Hỏa Ngục · Ăn Mòn
C17: Varus | D17: Diana | E17: Kog'Maw | F17: Vi | G17: 🛡 Amumu | H17: ⚔ Aphelios | I17: 🏹 Nidalee | J17: Người Đá | K17: Taric
B18: ⚔ Chủ lực chính | D18: Aphelios | F18: Cuồng Đao Guinsoo | H18: Vô Cực Kiếm | J18: Thịnh Nộ Thủy Quái | K18: Thay thế: Kiếm Tử Thần, Cung Xanh · Tạo Tác: Đại Bác Hải Tặc
B19: 🏹 Chủ lực phụ | D19: Nidalee | F19: Vô Cực Kiếm | H19: Ngọn Giáo Shojin | J19: Móng Vuốt Sterak | K19: Thay thế: Áo Choàng Bóng Tối + Áo Choàng Thủy Ngân + Vô Cực Kiếm · Tạo Tác: Chùy Bạch Ngân
B20: 🛡 Đỡ đòn chính | D20: Amumu | F20: Thú Tượng Thạch Giáp | H20: Giáp Máu Warmog | J20: Giáp Tâm Linh | K20: Người Đá: 2–3 Lời Thề Hộ Vệ, Áo Choàng Lửa
B21: ✨ Lõi nên chọn | D21: Thợ Rèn Kiếm | F21: Đam Mê Kiếm | H21: Thép Mạ Vàng | J21: Quái Thú Bên Trong
B23: S | C23: #3 Sivir & Nidalee Nguyên Sinh | K23: Lên 8 nhanh · Trung bình
B24: ĐỘI HÌNH CUỐI | L24: ⚔ chủ lực chính · 🏹 chủ lực phụ · 🛡 đỡ đòn chính Màu ô tên = giá tướng (xám 1 · xanh lá 2 · xanh dương 3 · tím 4 · vàng 5) Tộc/Hệ: 3 Thợ Săn · 3 Quái Rừng · 2 Nguyên Sinh · 2 Thích Ứng · 2 Gai Đen · 2 Đấu Sĩ · 2 Thuật Sĩ · Cự Thạch
C25: Mầm Non | D25: Rek'Sai | E25: Quái Đá Krug | F25: Kog'Maw | G25: 🛡 Malphite | H25: 🏹 Nidalee | I25: ⚔ Sivir | J25: Người Đá | K25: Ashe
B26: ⚔ Chủ lực chính | D26: Sivir | F26: Vô Cực Kiếm | H26: Kiếm Tử Thần | J26: Bùa Xanh | K26: Ngọn Giáo Shojin thay Bùa Xanh; Chùy Đoản Côn / Bùa Đỏ
B27: 🏹 Chủ lực phụ | D27: Nidalee | F27: Vô Cực Kiếm | H27: Ngọn Giáo Shojin | J27: Móng Vuốt Sterak | K27: Bàn Tay Công Lý thay Móng Vuốt Sterak
B28: 🛡 Đỡ đòn chính | D28: Malphite | F28: Thú Tượng Thạch Giáp | H28: Vương Miện Hoàng Gia | J28: Giáp Máu Warmog | K28: Tạo Tác: Huy Hiệu Thánh Khiên / Khiên Hừng Đông (lên hạng S)
B29: ✨ Lõi nên chọn | D29: Thợ Rèn Kiếm | F29: Đam Mê Kiếm (+2 bậc) | H29: Xúc Xắc Hoành Tráng | J29: Xúc Xắc Vô Tận | K29: Khác: Ấn Thợ Săn / Nguyên Sinh
B31: A | C31: #4 Kha'Zix Khắc Tinh (Thần Rừng Đao Phủ) | K31: Săn 3 sao 3 vàng (đổi tướng ở cấp 7) · Trung bình
B32: ĐỘI HÌNH CUỐI | L32: ⚔ chủ lực chính · 🏹 chủ lực phụ · 🛡 đỡ đòn chính Màu ô tên = giá tướng (xám 1 · xanh lá 2 · xanh dương 3 · tím 4 · vàng 5) Tộc/Hệ: 3 Đao Phủ · 3 Thần Rừng · 2 Thực Vật · 2 Vệ Quân · 2 Mặt Trăng · Khắc Tinh
C33: Ornn | D33: 🛡 Hecarim | E33: Fiddlesticks | F33: Diana | G33: ⚔ Kha'Zix | H33: Soraka | I33: 🏹 Aphelios | J33: Ezreal
B34: ⚔ Chủ lực chính | D34: Kha'Zix | F34: Áo Choàng Bóng Tối | H34: Bàn Tay Công Lý | J34: Mũ Phù Thủy Rabadon | K34: Tạo Tác Kiếm Tai Ương là đồ chuẩn số 1 (đẩy đội lên mức cao nhất) · Thay thế: Găng Bảo Thạch, Chùy Đoản Côn
B35: 🏹 Chủ lực phụ | D35: Aphelios | F35: Cuồng Đao Guinsoo | H35: Vô Cực Kiếm | J35: Thịnh Nộ Thủy Quái | K35: Chủ lực phụ; Ezreal cũng cầm được đồ dư (Ngọn Giáo Shojin, Cung Xanh)
B36: 🛡 Đỡ đòn chính | D36: Hecarim | F36: Thú Tượng Thạch Giáp | H36: Áo Choàng Lửa | J36: Giáp Máu Warmog | K36: Ornn: Áo Choàng Gai, Giáp Tâm Linh · Cây Thần Rừng lấp tuyến trước
B37: ✨ Lõi nên chọn | D37: Không Đối Thủ | F37: Nồi Nấu Ăn | H37: Giữ Vững Hàng Ngũ | K37: Khác: Kiếm Tai Ương (Tạo Tác), Ấn Đao Phủ
B39: A | C39: #5 Ahri & Morgana Thuật Sĩ | K39: Lên 8 nhanh · Trung bình
B40: ĐỘI HÌNH CUỐI | L40: ⚔ chủ lực chính · 🏹 chủ lực phụ · 🛡 đỡ đòn chính Màu ô tên = giá tướng (xám 1 · xanh lá 2 · xanh dương 3 · tím 4 · vàng 5) Tộc/Hệ: 3 Thuật Sĩ · 3 Hoa Linh · 3 Quái Rừng · 2 Thuật Sư · 2 Đấu Sĩ · 2 Tiên Phong
C41: Karma | D41: Sỏi | E41: Quái Đá Krug | F41: Sett | G41: ⚔ Ahri | H41: 🏹 Morgana | I41: 🛡 Người Đá | J41: Taric | K41: Lux
B42: ⚔ Chủ lực chính | D42: Ahri | F42: Găng Bảo Thạch | H42: Ngọn Giáo Shojin | J42: Chùy Đoản Côn | K42: Thay thế: Nanh Nashor · Tạo Tác: Khế Ước Vĩnh Hằng
B43: 🏹 Chủ lực phụ | D43: Morgana | F43: Quỷ Thư Morello | H43: Trượng Hư Vô | J43: Mũ Phù Thủy Rabadon | K43: Bắt buộc có Quỷ Thư Morello + Trượng Hư Vô · Tạo Tác: Đá Hắc Hóa
B44: 🛡 Đỡ đòn chính | D44: Người Đá | F44: Lời Thề Hộ Vệ | H44: Áo Choàng Lửa | J44: Thú Tượng Thạch Giáp | K44: Sett: Giáp Máu Warmog, Thú Tượng Thạch Giáp, Giáp Tâm Linh
B45: ✨ Lõi nên chọn | D45: Sinh Nhật Đoàn Tụ | F45: Kỳ Vọng Bất Ngờ | H45: Xúc Xắc Hoành Tráng | K45: Khác: Ấn Thuật Sĩ (lên S+)
B47: A | C47: #6 Ashe Hoa Linh Lên 9 | K47: Lên 9 nhanh · Khó
B48: ĐỘI HÌNH CUỐI | L48: ⚔ chủ lực chính · 🏹 chủ lực phụ · 🛡 đỡ đòn chính Màu ô tên = giá tướng (xám 1 · xanh lá 2 · xanh dương 3 · tím 4 · vàng 5) Tộc/Hệ: 5 Hoa Linh · 2 Thuật Sư · 2 Đấu Sĩ · 2 Dũng Sĩ · Tiên Phong
...

Sheet TRỢ LÝ VÁN ĐẤU
B2: 🌿 TRỢ LÝ VÁN ĐẤU | L2: v1.8 · 06/10/2026
B3: Chọn tình huống hiện tại → biết ngay nên LÊN CẤP, ĐỔI TƯỚNG hay GIỮ VÀNG | L3: Bản 18.3b · 18.4 ra 07/10
B4: ◄ Về Trang Chủ
B6: ① Lối chơi | E6: Lên 8 nhanh (tướng 4 vàng) | J6: ="💡 Đội hình hợp với lối chơi này:"&CHAR(10)&INDEX(DATA!$DW$2:$DW$6,MATCH($E$6,DATA!$DV$2:$DV$6,0)) -> 💡 Đội hình hợp với lối chơi này: • [S] Đao Phủ Azir – Soraka & Zyra (Thực Vật) • [S] Nidalee & Aphelios Mặt Trăng • [S] Sivir & Nidalee Nguyên Sinh • [A] Ahri & Morgana Thuật Sĩ • [C] Cassiopeia Tiên Hắc Ám (Tà Thuật – ĐANG TẮT)
B7: ② Giai đoạn (vòng) | E7: 4-2
B8: ③ Chuỗi hiện tại | E8: Đang THẮNG liên tiếp
B9: ④ Máu hiện tại | E9: Từ 40 đến 70 máu
B10: ⑤ Vàng đang có | E10: 50
B12: KHUYẾN NGHỊ NGAY BÂY GIỜ
B13: CẤP MỤC TIÊU | E13: VÀNG MỤC TIÊU | H13: LÃI VÒNG TỚI | K13: CẦN THÊM ĐỂ LÊN MỐC LÃI
B14: =INDEX(DATA!$DO$2:$DO$61,MATCH($E$6&"|"&$E$7,DATA!$DN$2:$DN$61,0)) -> 8 | E14: =INDEX(DATA!$DP$2:$DP$61,MATCH($E$6&"|"&$E$7,DATA!$DN$2:$DN$61,0)) -> còn 10–20 sau khi đổi | H14: ="+"&MIN(5,INT($E$10/10))&" vàng" -> +5 vàng | K14: =IF($E$10>=50,"Đã tối đa (50+)","+"&(10-MOD($E$10,10))&" vàng") -> Đã tối đa (50+)
B16: 🎯 HÀNH ĐỘNG CHÍNH | E16: =INDEX(DATA!$DQ$2:$DQ$61,MATCH($E$6&"|"&$E$7,DATA!$DN$2:$DN$61,0)) -> MỐC ĐỔI TƯỚNG: lên 8 + Lõi 3 → dồn vàng tìm chủ lực & đỡ đòn 4 vàng 2 sao.
B17: 📍 Sự kiện vòng này | E17: =INDEX(DATA!$DS$2:$DS$61,MATCH($E$6&"|"&$E$7,DATA!$DN$2:$DN$61,0)) -> Chọn Lõi 3
B18: 🔥 Theo chuỗi | E18: =INDEX(DATA!$DZ$2:$DZ$4,MATCH($E$8,DATA!$DY$2:$DY$4,0)) -> Giữ chuỗi bằng cách lên cấp sớm hơn 1 mốc & mua Tinh Linh giao tranh rẻ. Chưa đổi tướng; dùng vàng thưởng chuỗi để lên cấp.
B19: ❤️ Theo máu | E19: =INDEX(DATA!$EB$2:$EB$4,MATCH($E$9,DATA!$EA$2:$EA$4,0)) -> Theo đúng lộ trình chuẩn. Thua 2 trận liên tiếp ở Giai đoạn 4 → đổi tướng cho ổn định.
B20: 💰 Kiểm tra vàng | E20: =IF($E$10<10,"Vàng rất thấp – ưu tiên tích lãi, không mua Tinh Linh mất phí.",IF($E$10<30,"Đang tích lũy – đừng để tụt mốc "&INT($E$10/10)*10&" vàng.",IF($E$10<50,"Gần tối đa lãi – cố giữ tới 50 trước khi đổi tướng (nếu máu cho phép).","Đủ 50+: chỉ dùng phần vàng TRÊN 50 để đổi tướng / mua Tinh Linh."))) -> Đủ 50+: chỉ dùng phần vàng TRÊN 50 để đổi tướng / mua Tinh Linh.
B22: TỈ LỆ RA TƯỚNG Ở CẤP MỤC TIÊU (mỗi ô cửa hàng)
B23: Cấp | D23: 1 vàng | F23: 2 vàng | H23: 3 vàng | J23: 4 vàng | L23: 5 vàng
B24: =INDEX(DATA!$DR$2:$DR$61,MATCH($E$6&"|"&$E$7,DATA!$DN$2:$DN$61,0)) -> 8 | D24: =INDEX(DATA!$EF$2:$EF$11,MATCH($B$24,DATA!$EE$2:$EE$11,0))/100 -> 0.15 | F24: =INDEX(DATA!$EG$2:$EG$11,MATCH($B$24,DATA!$EE$2:$EE$11,0))/100 -> 0.2 | H24: =INDEX(DATA!$EH$2:$EH$11,MATCH($B$24,DATA!$EE$2:$EE$11,0))/100 -> 0.32 | J24: =INDEX(DATA!$EI$2:$EI$11,MATCH($B$24,DATA!$EE$2:$EE$11,0))/100 -> 0.3 | L24: =INDEX(DATA!$EJ$2:$EJ$11,MATCH($B$24,DATA!$EE$2:$EE$11,0))/100 -> 0.03
B26: LỘ TRÌNH ĐẦY ĐỦ CỦA LỐI CHƠI ĐÃ CHỌN
B27: Vòng | C27: Cấp | E27: Vàng | G27: Việc cần làm
B28: 1-x | C28: =INDEX(DATA!$DO$2:$DO$61,MATCH($E$6&"|"&$B28,DATA!$DN$2:$DN$61,0)) -> 3 | E28: =INDEX(DATA!$DP$2:$DP$61,MATCH($E$6&"|"&$B28,DATA!$DN$2:$DN$61,0)) -> — | G28: =INDEX(DATA!$DQ$2:$DQ$61,MATCH($E$6&"|"&$B28,DATA!$DN$2:$DN$61,0)) -> Nhặt đồ theo hướng đội hình; mua cặp tướng; chưa đổi tướng.
B29: 2-1 | C29: =INDEX(DATA!$DO$2:$DO$61,MATCH($E$6&"|"&$B29,DATA!$DN$2:$DN$61,0)) -> 4 | E29: =INDEX(DATA!$DP$2:$DP$61,MATCH($E$6&"|"&$B29,DATA!$DN$2:$DN$61,0)) -> ≥ 10 sau khi lên | G29: =INDEX(DATA!$DQ$2:$DQ$61,MATCH($E$6&"|"&$B29,DATA!$DN$2:$DN$61,0)) -> Lên cấp 4 · Lõi 1 kinh tế/trang bị · Ghép sớm 1–2 món mạnh cho tướng tạm.
B30: 2-3 | C30: =INDEX(DATA!$DO$2:$DO$61,MATCH($E$6&"|"&$B30,DATA!$DN$2:$DN$61,0)) -> 4 | E30: =INDEX(DATA!$DP$2:$DP$61,MATCH($E$6&"|"&$B30,DATA!$DN$2:$DN$61,0)) -> 10–20 | G30: =INDEX(DATA!$DQ$2:$DQ$61,MATCH($E$6&"|"&$B30,DATA!$DN$2:$DN$61,0)) -> Giữ mốc lãi; mua Tinh Linh 0–1 vàng; bán tướng lẻ không có cặp.
B31: 2-5 | C31: =INDEX(DATA!$DO$2:$DO$61,MATCH($E$6&"|"&$B31,DATA!$DN$2:$DN$61,0)) -> 5 | E31: =INDEX(DATA!$DP$2:$DP$61,MATCH($E$6&"|"&$B31,DATA!$DN$2:$DN$61,0)) -> 20–30 | G31: =INDEX(DATA!$DQ$2:$DQ$61,MATCH($E$6&"|"&$B31,DATA!$DN$2:$DN$61,0)) -> Lên cấp 5 (chuỗi thắng: ở 2-5; chuỗi thua: có thể đã lên ở 2-3).
B32: 3-1 | C32: =INDEX(DATA!$DO$2:$DO$61,MATCH($E$6&"|"&$B32,DATA!$DN$2:$DN$61,0)) -> 6 | E32: =INDEX(DATA!$DP$2:$DP$61,MATCH($E$6&"|"&$B32,DATA!$DN$2:$DN$61,0)) -> 30 | G32: =INDEX(DATA!$DQ$2:$DQ$61,MATCH($E$6&"|"&$B32,DATA!$DN$2:$DN$61,0)) -> Lên cấp 6 · Giữ 3 tướng mạnh nhất có cặp; chưa đổi tướng.
B33: 3-2 | C33: =INDEX(DATA!$DO$2:$DO$61,MATCH($E$6&"|"&$B33,DATA!$DN$2:$DN$61,0)) -> 6 | E33: =INDEX(DATA!$DP$2:$DP$61,MATCH($E$6&"|"&$B33,DATA!$DN$2:$DN$61,0)) -> 30–40 | G33: =INDEX(DATA!$DQ$2:$DQ$61,MATCH($E$6&"|"&$B33,DATA!$DN$2:$DN$61,0)) -> Lõi 2 khớp hướng đội hình · Đang thua liên tục: lên 6 tại đây nếu chưa lên.
B34: 3-5 | C34: =INDEX(DATA!$DO$2:$DO$61,MATCH($E$6&"|"&$B34,DATA!$DN$2:$DN$61,0)) -> 7 | E34: =INDEX(DATA!$DP$2:$DP$61,MATCH($E$6&"|"&$B34,DATA!$DN$2:$DN$61,0)) -> 40–50 | G34: =INDEX(DATA!$DQ$2:$DQ$61,MATCH($E$6&"|"&$B34,DATA!$DN$2:$DN$61,0)) -> Lên cấp 7 sau băng chuyền · Chỉ đổi tướng nếu máu < 50.
B35: 4-1 | C35: =INDEX(DATA!$DO$2:$DO$61,MATCH($E$6&"|"&$B35,DATA!$DN$2:$DN$61,0)) -> 7 → 8 | E35: =INDEX(DATA!$DP$2:$DP$61,MATCH($E$6&"|"&$B35,DATA!$DN$2:$DN$61,0)) -> 50 | G35: =INDEX(DATA!$DQ$2:$DQ$61,MATCH($E$6&"|"&$B35,DATA!$DN$2:$DN$61,0)) -> Đang thua liên tục / máu thấp: lên 8 ngay và đổi tướng cho ổn.
B36: 4-2 | C36: =INDEX(DATA!$DO$2:$DO$61,MATCH($E$6&"|"&$B36,DATA!$DN$2:$DN$61,0)) -> 8 | E36: =INDEX(DATA!$DP$2:$DP$61,MATCH($E$6&"|"&$B36,DATA!$DN$2:$DN$61,0)) -> còn 10–20 sau khi đổi | G36: =INDEX(DATA!$DQ$2:$DQ$61,MATCH($E$6&"|"&$B36,DATA!$DN$2:$DN$61,0)) -> MỐC ĐỔI TƯỚNG: lên 8 + Lõi 3 → dồn vàng tìm chủ lực & đỡ đòn 4 vàng 2 sao.
B37: 4-5 | C37: =INDEX(DATA!$DO$2:$DO$61,MATCH($E$6&"|"&$B37,DATA!$DN$2:$DN$61,0)) -> 8 | E37: =INDEX(DATA!$DP$2:$DP$61,MATCH($E$6&"|"&$B37,DATA!$DN$2:$DN$61,0)) -> tích lại 50 | G37: =INDEX(DATA!$DQ$2:$DQ$61,MATCH($E$6&"|"&$B37,DATA!$DN$2:$DN$61,0)) -> Đội đã ổn: không đổi tướng, tích lại 50 vàng · Chưa ổn: đổi tướng nhẹ để giữ máu.
B38: 5-1 | C38: =INDEX(DATA!$DO$2:$DO$61,MATCH($E$6&"|"&$B38,DATA!$DN$2:$DN$61,0)) -> 8 → 9 | E38: =INDEX(DATA!$DP$2:$DP$61,MATCH($E$6&"|"&$B38,DATA!$DN$2:$DN$61,0)) -> 50+ | G38: =INDEX(DATA!$DQ$2:$DQ$61,MATCH($E$6&"|"&$B38,DATA!$DN$2:$DN$61,0)) -> Máu > 50 và đội ổn: chuẩn bị lên 9.
B39: 5-2+ | C39: =INDEX(DATA!$DO$2:$DO$61,MATCH($E$6&"|"&$B39,DATA!$DN$2:$DN$61,0)) -> 9 | E39: =INDEX(DATA!$DP$2:$DP$61,MATCH($E$6&"|"&$B39,DATA!$DN$2:$DN$61,0)) -> dồn vàng đổi tướng | G39: =INDEX(DATA!$DQ$2:$DQ$61,MATCH($E$6&"|"&$B39,DATA!$DN$2:$DN$61,0)) -> Lên 9 · đổi tướng tìm tướng 5 vàng / 4 vàng 2 sao · thay tướng yếu.

Sheet LÊN ĐỒ
B2: 🌿 LÊN ĐỒ & GHÉP TRANG BỊ | L2: v1.8 · 06/10/2026
B3: Chọn 2 mảnh đồ → biết ngay món ghép ra, ai dùng, và đội hình nào hợp | L3: Bản 18.3b · 18.4 ra 07/10
B4: ◄ Về Trang Chủ
B6: ① Mảnh đồ thứ 1 | E6: Kiếm BF | J6: KẾT QUẢ GHÉP
B7: ② Mảnh đồ thứ 2 | E7: Găng Đấu Tập | J7: =INDEX(DATA!$BQ$2:$BY$10,MATCH($E$6,DATA!$BN$2:$BN$10,0),MATCH($E$7,DATA!$BN$2:$BN$10,0)) -> Vô Cực Kiếm
B10: Công thức ghép | E10: =INDEX(DATA!$BG$2:$BG$46,MATCH($J$7,DATA!$BF$2:$BF$46,0)) -> Kiếm BF + Găng Đấu Tập
B11: Dành cho | E11: =INDEX(DATA!$BH$2:$BH$46,MATCH($J$7,DATA!$BF$2:$BF$46,0)) -> Chủ lực vật lý
B12: Tác dụng | E12: =INDEX(DATA!$BI$2:$BI$46,MATCH($J$7,DATA!$BF$2:$BF$46,0)) -> Tỉ Lệ Chí Mạng + sát thương chí mạng; kỹ năng có thể chí mạng.
B13: Tướng nên cầm | E13: =INDEX(DATA!$BJ$2:$BJ$46,MATCH($J$7,DATA!$BF$2:$BF$46,0)) -> Nidalee, Sivir, Aphelios, Rồng Ngàn Tuổi, Kog'Maw
B15: ĐỒ KHỞI ĐẦU → NÊN ĐI HƯỚNG ĐỘI HÌNH NÀO?
B16: ③ Mảnh đồ bạn có nhiều nhất | E16: Gậy Quá Khổ | J16: ="Chỉ số: "&INDEX(DATA!$BO$2:$BO$10,MATCH($E$16,DATA!$BN$2:$BN$10,0)) -> Chỉ số: + SMPT (Sức Mạnh Phép Thuật)
B17: =INDEX(DATA!$CA$2:$CA$10,MATCH($E$16,DATA!$BN$2:$BN$10,0)) -> • Đao Phủ Azir – Soraka & Zyra (Thực Vật) [S] → Găng Bảo Thạch, Mũ Phù Thủy Rabadon • Nidalee & Aphelios Mặt Trăng [S] → Cuồng Đao Guinsoo • Kha'Zix Khắc Tinh (Thần Rừng Đao Phủ) [A] → Mũ Phù Thủy Rabadon, Cuồng Đao Guinsoo • Ahri & Morgana Thuật Sĩ [A] → Găng Bảo Thạch, Quỷ Thư Morello, Mũ Phù Thủy Rabadon • Ashe Hoa Linh Lên 9 [A] → Găng Bảo Thạch • Draven Lên 9 (Thần Rừng Đao Phủ) [A] → Cuồng Đao Guinsoo • Caitlyn Dũng Sĩ Thợ Săn [B] → Cuồng Đao Guinsoo
B23: BẢNG GHÉP ĐỒ 9 × 9 (ô vàng = cặp mảnh đồ bạn đang chọn)
B24: ＋ | C24: Kiếm BF | D24: Cung Gỗ | E24: Gậy | F24: Nước Mắt | G24: Giáp Lưới | H24: Áo Choàng | I24: Đai | J24: Găng | K24: Xẻng | L24: Chỉ số của mảnh đồ
B25: Kiếm BF | C25: Kiếm Tử Thần | D25: Diệt Khổng Lồ | E25: Kiếm Súng Hextech | F25: Ngọn Giáo Shojin | G25: Áo Choàng Bóng Tối | H25: Huyết Kiếm | I25: Móng Vuốt Sterak | J25: Vô Cực Kiếm | K25: Ấn tộc/hệ | L25: Kiếm BF → + SMCK (Sức Mạnh Công Kích)
B26: Cung Gỗ | C26: Diệt Khổng Lồ | D26: Bùa Đỏ | E26: Cuồng Đao Guinsoo | F26: Trượng Hư Vô | G26: Quyền Năng Khổng Lồ | H26: Thịnh Nộ Thủy Quái | I26: Nanh Nashor | J26: Cung Xanh | K26: Ấn tộc/hệ | L26: Cung Gỗ → + Tốc Độ Đánh
B27: Gậy | C27: Kiếm Súng Hextech | D27: Cuồng Đao Guinsoo | E27: Mũ Phù Thủy Rabadon | F27: Quyền Trượng Thiên Thần | G27: Vương Miện Hoàng Gia | H27: Nỏ Sét | I27: Quỷ Thư Morello | J27: Găng Bảo Thạch | K27: Ấn tộc/hệ | L27: Gậy Quá Khổ → + SMPT (Sức Mạnh Phép Thuật)
B28: Nước Mắt | C28: Ngọn Giáo Shojin | D28: Trượng Hư Vô | E28: Quyền Trượng Thiên Thần | F28: Bùa Xanh | G28: Lời Thề Hộ Vệ | H28: Mũ Thích Nghi | I28: Giáp Tâm Linh | J28: Bàn Tay Công Lý | K28: Ấn tộc/hệ | L28: Nước Mắt Nữ Thần → + Năng Lượng
B29: Giáp Lưới | C29: Áo Choàng Bóng Tối | D29: Quyền Năng Khổng Lồ | E29: Vương Miện Hoàng Gia | F29: Lời Thề Hộ Vệ | G29: Áo Choàng Gai | H29: Thú Tượng Thạch Giáp | I29: Áo Choàng Lửa | J29: Trái Tim Kiên Định | K29: Ấn tộc/hệ | L29: Giáp Lưới → + Giáp
B30: Áo Choàng | C30: Huyết Kiếm | D30: Thịnh Nộ Thủy Quái | E30: Nỏ Sét | F30: Mũ Thích Nghi | G30: Thú Tượng Thạch Giáp | H30: Vuốt Rồng | I30: Giáp Vai Nguyệt Thần | J30: Áo Choàng Thủy Ngân | K30: Ấn tộc/hệ | L30: Áo Choàng Bạc → + Kháng Phép
B31: Đai | C31: Móng Vuốt Sterak | D31: Nanh Nashor | E31: Quỷ Thư Morello | F31: Giáp Tâm Linh | G31: Áo Choàng Lửa | H31: Giáp Vai Nguyệt Thần | I31: Giáp Máu Warmog | J31: Chùy Đoản Côn | K31: Ấn tộc/hệ | L31: Đai Khổng Lồ → + Máu
B32: Găng | C32: Vô Cực Kiếm | D32: Cung Xanh | E32: Găng Bảo Thạch | F32: Bàn Tay Công Lý | G32: Trái Tim Kiên Định | H32: Áo Choàng Thủy Ngân | I32: Chùy Đoản Côn | J32: Găng Đạo Tặc | K32: Ấn tộc/hệ | L32: Găng Đấu Tập → + Tỉ Lệ Chí Mạng
B33: Xẻng | C33: Ấn tộc/hệ | D33: Ấn tộc/hệ | E33: Ấn tộc/hệ | F33: Ấn tộc/hệ | G33: Ấn tộc/hệ | H33: Ấn tộc/hệ | I33: Ấn tộc/hệ | J33: Ấn tộc/hệ | K33: Vương Miện Chiến Thuật | L33: Xẻng Vàng → Dùng để ghép Ấn tộc/hệ
B35: TẠO TÁC · ĐỒ ÁNH SÁNG · ĐỒ ĐẶC BIỆT NỔI BẬT (18.3b)
B36: Hình | C36: Tên | E36: Loại | G36: Tướng hợp nhất | K36: Ghi chú
C37: Đại Bác Hải Tặc | E37: Tạo Tác (Ornn) | G37: Aphelios, Nidalee, Yunara | K37: Kết liễu kẻ dưới 12% Máu, hạ gục có thể rơi vàng. ⚠ 18.3: giảm SMCK (40% → 35%) nhưng vẫn rất mạnh
C38: Kiếm Tai Ương | E38: Tạo Tác (Ornn) | G38: Kha'Zix, Akali, Veigar | K38: Đồ chuẩn số 1 của Kha'Zix (18.3: Kha'Zix là đội mạnh nhất); Akali dạng phép có món này gần như chắc thắng
C39: Đá Hắc Hóa | E39: Tạo Tác (Ornn) | G39: Morgana, Cassiopeia, Aphelios | K39: Chủ lực phép xuyên kháng
C40: Lõi Bình Minh | E40: Tạo Tác (Ornn) | G40: Veigar, Soraka, Yunara, Cassiopeia | K40: Chủ lực tung chiêu
C41: Khế Ước Vĩnh Hằng | E41: Tạo Tác (Ornn) | G41: Ahri, Veigar, Cassiopeia | K41: Đồ chuẩn của Ahri
C42: Chùy Bạch Ngân | E42: Tạo Tác (Ornn) | G42: Nidalee | K42: Miễn choáng, đòn đánh gây choáng – đồ chuẩn Nidalee
C43: Đao Chớp | E43: Tạo Tác (Ornn) | G43: Tristana, Caitlyn, Kayle | K43: Chủ lực đánh thường
C44: Đao Tím / Rìu Hỏa Ngục | E44: Tạo Tác (Ornn) | G44: Master Yi, Kayle | K44: Chủ lực cận chiến / đánh thường
C45: Giáp Tay Seeker | E45: Tạo Tác (Ornn) | G45: Kha'Zix, Kayle | K45: Chủ lực phép
C46: Huy Hiệu Thánh Khiên / Khiên Hừng Đông | E46: Tạo Tác phòng thủ | G46: Malphite, đỡ đòn chính | K46: Đẩy Sivir & Nidalee lên hạng S
C47: Thực Vật Hấp Thụ | E47: Lõi đặc biệt | G47: Veigar săn 3 sao | K47: Điều kiện bắt buộc cho đội Veigar (từ 18.2 chỉ 1 người/phòng)
C48: Trang bị Ánh Sáng | E48: Đồ nâng cấp | G48: Chủ lực đã đủ đồ | K48: Cuồng Đao Ánh Sáng (Rengar), Ngọn Giáo/Bùa Xanh Ánh Sáng (Yunara, Quái Rừng), Bùa Đỏ Ánh Sáng (Ashe)
B50: NGUYÊN TẮC LÊN ĐỒ CỦA THÁCH ĐẤU
B51: 1. Ghép đồ sớm ở Giai đoạn 2 để giữ chuỗi – một món mạnh bây giờ giá trị hơn món hoàn hảo ở Giai đoạn 4.
B52: 2. Ưu tiên đồ ĐỠ ĐÒN linh hoạt (Thú Tượng Thạch Giáp, Giáp Máu Warmog, Lời Thề Hộ Vệ, Áo Choàng Lửa): đỡ đòn nào cũng dùng được.
...

Sheet XẾP HẠNG ĐỘI HÌNH
B2: 🌿 XẾP HẠNG ĐỘI HÌNH · BẢN 18.3b | J2: v1.8 · 06/10/2026
B3: Tổng hợp từ nhiều trang thống kê uy tín — bấm nút ▼ ở dòng tiêu đề để lọc · Mùa 18 · Đại Ngàn Kỳ Bí · Bản vá 18.3b (đang chạy) · 18.4 ra 07/10/2026
B4: ◄ Về Trang Chủ
B6: ="S: "&COUNTIF($C$9:$C$27,"S")&" đội" -> S: 3 đội | D6: ="A: "&COUNTIF($C$9:$C$27,"A")&" đội" -> A: 5 đội | E6: ="B: "&COUNTIF($C$9:$C$27,"B")&" đội" -> B: 7 đội | G6: ="C: "&COUNTIF($C$9:$C$27,"C")&" đội" -> C: 4 đội | I6: Hạng có thể tăng 1–2 bậc khi có lõi/Ấn/Tạo Tác phù hợp
B8: # | C8: Hạng | D8: Hình | E8: Đội hình | F8: Lối chơi | G8: Độ khó | H8: Chủ lực chính | I8: Chủ lực phụ | J8: Đỡ đòn chính | K8: Tộc / Hệ | L8: Khi nào nên chơi
B9: 1 | C9: S | E9: Đao Phủ Azir – Soraka & Zyra (Thực Vật) | F9: Lên 8 nhanh | G9: Trung bình | H9: Soraka | I9: Zyra | J9: Rammus | K9: 4 Đao Phủ (có Ấn) · 3 Tinh Nghịch · 2 Thực Vật · 2 Triệu Hồi · 2 Gai Đen · 2 Thuật Sư · 2 Vệ Quân · Vườn Gai | L9: Có đồ phép + Găng; ít đội phép khác trong phòng. ⚠ 18.4 (07/10): Đao Phủ chảy máu giảm nhẹ (40% → 35%) – vẫn rất mạnh.
B10: 2 | C10: S | E10: Nidalee & Aphelios Mặt Trăng | F10: Lên 8 nhanh | G10: Trung bình | H10: Aphelios | I10: Nidalee | J10: Amumu | K10: 2 Mặt Trăng · 2 Liên Kích · 2 Nguyên Sinh · 2 Thích Ứng · 2 Dũng Sĩ · 2 Tiên Phong · 2 Hỏa Ngục · Ăn Mòn | L10: Có nhiều Kiếm BF/Găng; có Tạo Tác Đại Bác Hải Tặc; không ai tranh Nidalee.
B11: 3 | C11: S | E11: Sivir & Nidalee Nguyên Sinh | F11: Lên 8 nhanh | G11: Trung bình | H11: Sivir | I11: Nidalee | J11: Malphite | K11: 3 Thợ Săn · 3 Quái Rừng · 2 Nguyên Sinh · 2 Thích Ứng · 2 Gai Đen · 2 Đấu Sĩ · 2 Thuật Sĩ · Cự Thạch | L11: Nhiều Kiếm BF; có Ấn Thợ Săn/Nguyên Sinh; ít người chơi Nidalee.
B12: 4 | C12: A | E12: Kha'Zix Khắc Tinh (Thần Rừng Đao Phủ) | F12: Săn 3 sao 3 vàng (đổi tướng ở cấp 7) | G12: Trung bình | H12: Kha'Zix | I12: Aphelios | J12: Hecarim | K12: 3 Đao Phủ · 3 Thần Rừng · 2 Thực Vật · 2 Vệ Quân · 2 Mặt Trăng · Khắc Tinh | L12: Gặp Kha'Zix sớm (2-1 → 2-3) hoặc nhận Kha'Zix từ quả cầu; có Áo Choàng Bóng Tối.
B13: 5 | C13: A | E13: Ahri & Morgana Thuật Sĩ | F13: Lên 8 nhanh | G13: Trung bình | H13: Ahri | I13: Morgana | J13: Người Đá | K13: 3 Thuật Sĩ · 3 Hoa Linh · 3 Quái Rừng · 2 Thuật Sư · 2 Đấu Sĩ · 2 Tiên Phong | L13: Đầu game nhận nhiều Gậy/Nước Mắt; có Ấn Thuật Sĩ; trong phòng ít người chơi đội phép.
B14: 6 | C14: A | E14: Ashe Hoa Linh Lên 9 | F14: Lên 9 nhanh | G14: Khó | H14: Ashe | I14: Ahri | J14: Sett | K14: 5 Hoa Linh · 2 Thuật Sư · 2 Đấu Sĩ · 2 Dũng Sĩ · Tiên Phong | L14: Có Tiếng Gọi Hoa Linh / Tinh Linh Hoàn Tiền; nhiều Nước Mắt + Gậy; máu cao.
B15: 7 | C15: A | E15: Rồng Ngàn Tuổi Quái Rừng | F15: Lên 9 nhanh | G15: Khó | H15: Rồng Ngàn Tuổi | I15: Bụi Gai Đỏ | J15: Người Đá | K15: 7 Quái Rừng · Bá Chủ · 2 Tàn Phá · 2 Đấu Sĩ · 2 Tiên Phong · 2 Thuật Sĩ | L15: Có lõi kinh tế/kinh nghiệm, máu cao ở Giai đoạn 4; ít người cùng lên 9.
B16: 8 | C16: A | E16: Draven Lên 9 (Thần Rừng Đao Phủ) | F16: Lên 9 nhanh | G16: Khó | H16: Draven | I16: Ezreal | J16: Maokai | K16: 3 Thần Rừng · 2 Đao Phủ · 2 Đấu Sĩ · 2 Dũng Sĩ · 2 Hỏa Ngục · Săn Thưởng · Cổ Thụ · Thụ Thần · Lục Bảo | L16: Có lõi KINH TẾ hoặc chuỗi thắng dài; máu > 60 ở Giai đoạn 4. Không có lõi kinh tế thì gần như không lên 9 kịp.
B17: 9 | C17: B | E17: Caitlyn Dũng Sĩ Thợ Săn | F17: Săn 3 sao 2 vàng (đổi tướng từ từ ở cấp 6) | G17: Dễ | H17: Caitlyn | I17: Sivir | J17: Cua Kỳ Cục | K17: 4 Dũng Sĩ · 4 Thợ Săn · 2 Nguyên Sinh · 2 Tiên Linh | L17: Có Cuồng Đao + Thịnh Nộ Thủy Quái sớm; có từ 3 Caitlyn ở Giai đoạn 2.
B18: 10 | C18: B | E18: Veigar Thực Vật Hấp Thụ (Tinh Nghịch) | F18: Săn 3 sao 1 vàng (đổi tướng từ từ ở cấp 5) | G18: Dễ | H18: Veigar | I18: Teemo | J18: Rek'Sai | K18: 5 Tinh Nghịch · 4 Đấu Sĩ · 2 Thuật Sư · 2 Gai Đen · 2 Vệ Quân · Thực Vật | L18: CHỈ chơi khi có Thực Vật Hấp Thụ hoặc sớm có Veigar 3 sao.
B19: 11 | C19: B | E19: Yunara Mặt Trời (săn 3 sao) | F19: Săn 3 sao 2 vàng | G19: Trung bình | H19: Yunara | I19: Kayle | J19: Sejuani | K19: 3 Mặt Trời · 3 Hoa Linh · 2 Đao Phủ · 2 Dũng Sĩ · 2 Thuật Sư · Triệu Hồi | L19: Nhặt được nhiều Yunara sớm; có Tạo Tác cho Yunara.
B20: 12 | C20: B | E20: Azir Triệu Hồi (săn 3 sao) | F20: Săn 3 sao 3 vàng (đổi tướng ở cấp 7) | G20: Trung bình | H20: Azir | I20: Zyra | J20: Vi | K20: 3 Triệu Hồi · 3 Đao Phủ · 2 Hoa Linh · 2 Gai Đen · 2 Đấu Sĩ · 2 Dũng Sĩ | L20: Gặp nhiều Azir từ Giai đoạn 2; có Gậy Quá Khổ sớm.
... B27: 19 | C27: C | E27: Cassiopeia Tiên Hắc Ám (Tà Thuật – ĐANG TẮT) | F27: Lên 8 nhanh | G27: Trung bình | H27: Cassiopeia | I27: Morgana | J27: Người Đá | K27: 3 Tiên Hắc Ám · 2 Thuật Sư · 2 Tiên Phong · 2 Mặt Trăng · 2 Thần Rừng · Thụ Thần · Hòa Hợp | L27: ⛔ 18.3b: lõi Tà Thuật đang bị tắt nên chưa chơi được. Khi bật lại: nhận ở 2-1 hoặc 3-2 thì ép luôn.
B29: Mẹo: bấm tên đội hình để xem HÌNH ẢNH đội hình (tướng + đồ + lõi); muốn xem lộ trình chi tiết thì mở trang CHỌN ĐỘI HÌNH. Xếp hạng tổng hợp ngày 06/10/2026 – đội mạnh sẽ thay đổi sau mỗi phiên bản (~2 tuần).

Sheet MÁY CHỦ VN - TRUNG - HÀN
B2: 🌿 SỐ LIỆU VN · TRUNG · HÀN | G2: v1.8 · 06/10/2026
B3: OP.GG lọc riêng máy chủ Việt Nam (18.3b, 06/10) + TopMeta Trung Quốc (18.3b) + OP.GG Hàn/quốc tế, kèm cách build từng bước · Mùa 18 · Đại Ngàn Kỳ Bí · Bản vá 18.3b (đang chạy) · 18.4 ra 07/10/2026
B4: ◄ Về Trang Chủ
B6: ★ MÁY CHỦ VIỆT NAM (VN) – OP.GG, bản 18.3b, 589.544 ván / 24 giờ (06/10) – ĐỌC BẢNG NÀY TRƯỚC
B7: # | C7: Đội hình | D7: Bậc | E7: Hạng TB | F7: Top 4 | G7: Tỉ lệ chơi | H7: Tướng chính
B8: 1 | C8: Đao Phủ Azir (Thực Vật) | D8: S | E8: 2.69 | F8: 84,8% | G8: 1,15% | H8: Veigar, Teemo, Azir, Fiddlesticks, Rammus, Soraka, Zyra, Kennen
B9: 2 | C9: Dũng Sĩ Ashe | D9: S | E9: 2.77 | F9: 79,3% | G9: 0,54% | H9: Rakan, Vi, Amumu, Sivir, Ashe, Ivern, Kennen, Maokai, Taric
